Workbook

Sheet 1.Loading
A1: Container No. | B1: EQ Date | C1: Vessel | D1: Voyage | E1: Type Size | F1: CD | G1: R.C.V | H1: P.O.L | I1: P.O.D | J1: D.L.V | K1: F/E | L1: LEASE_TYPE | M1: Move Code | N1: Location | O1: Area | P1: Nation | Q1: Booking No. | R1: T/S | S1: S.O.C | T1: Service | U1: Remark | V1: Auth. No. | W1: Shipper | X1: PreVSLMove | Y1: Consignee | Z1: Notify | AA1: CNTR WGT. | AB1: L-Wharf(B/L) | AC1: D-Wharf(B/L)
A2: DFSU7561434 | B2: 2026-10-04 | C2: KMBK | D2: 2611N | E2: 45GP | F2: SD | G2: THLCH | H2: THLCH | I2: KRPUS | J2: RUVVO | K2: F | L2: ONE | M2: VFL | N2: LCH04 | O2: LCH | P2: TH | Q2: HASLS22260900886 | R2: Y | S2: N | T2: KHS | V2: K0120023 | W2: ROHLIG (THAILAND) LIMITED | X2: ONL | Y2: RECKITT BENCKISER HEALTHCARE LLC | Z2: SUUS LOGISTICS LTD | AA2: 11462.038 | AB2: LCH04 | AC2: VVO01
A3: FBIU5090221 | B3: 2026-10-04 | C3: KMBK | D3: 2611N | E3: 45RE | F3: SD | G3: THLCH | H3: THLCH | I3: KRPUS | J3: KRPUS | K3: F | L3: ONE | M3: VFL | N3: LCH04 | O3: LCH | P3: TH | Q3: HASLS22260902143 | R3: N | S3: N | T3: KHS | V3: K0120025 | W3: KAONA POULTRY CO., LTD. | X3: VFD | Y3: TO THE ORDER OF INDUSTRIAL BANK OF | Z3: NEW ASIA CO.,LTD. | AA3: 24444 | AB3: LCH04 | AC3: PUS05
A4: FBIU5092585 | B4: 2026-10-04 | C4: KMBK | D4: 2611N | E4: 45RE | F4: SD | G4: THLCH | H4: THLCH | I4: KRPUS | J4: KRPUS | K4: F | L4: ONE | M4: VFL | N4: LCH04 | O4: LCH | P4: TH | Q4: HASLS22260901848 | R4: N | S4: N | T4: KHS | V4: K0120025 | W4: GFPT PUBLIC COMPANY LIMITED | X4: VFD | Y4: TO THE ORDER OF WOORI BANK SEOUL | Z4: IATS CO.,LTD | AA4: 24000 | AB4: LCH04 | AC4: PUS05
A5: FBIU5102214 | B5: 2026-10-04 | C5: KMBK | D5: 2611N | E5: 45RE | F5: SD | G5: THLCH | H5: THLCH | I5: VNSGN | J5: VNSGN | K5: F | L5: L/T | M5: VFL | N5: LCH04 | O5: LCH | P5: TH | Q5: HASLS22260901768 | R5: N | S5: N | T5: KHS | V5: C0321002 | W5: GOLDEN SEA FROZEN FOODS CO.,LTD. | X5: VFD | Y5: KHANH LAN SEAFOOD IMPORT & EXPORT | Z5: KHANH LAN SEAFOOD IMPORT & EXPORT | AA5: 27666 | AB5: LCH04 | AC5: SGN03
A6: FBIU5371492 | B6: 2026-10-04 | C6: KMBK | D6: 2611N | E6: 45RE | F6: SD | G6: THLCH | H6: THLCH | I6: KRPUS | J6: JPSDJ | K6: F | L6: L/T | M6: VFL | N6: LCH04 | O6: LCH | P6: TH | Q6: HASLS22260901282 | R6: Y | S6: N | T6: KHS | V6: C0323004 | W6: KODAI (THAILAND) CO., LTD. | X6: VFD | Y6: KODAI COMPANY LTD. | Z6: KODAI COMPANY LTD. | AA6: 25479.09 | AB6: LCH04 | AC6: SDJ01
A7: FBIU5373392 | B7: 2026-10-04 | C7: KMBK | D7: 2611N | E7: 45RE | F7: SD | G7: THLCH | H7: THLCH | I7: KRPUS | J7: JPISS | K7: F | L7: ONE | M7: VFL | N7: LCH04 | O7: LCH | P7: TH | Q7: HASLS22260901278 | R7: Y | S7: N | T7: KHS | V7: K0120025 | W7: KODAI (THAILAND) CO., LTD. | X7: VFD | Y7: KODAI COMPANY LTD. | Z7: KODAI COMPANY LTD. | AA7: 25479.09 | AB7: LCH04 | AC7: ISS02
A8: FSCU5835676 | B8: 2026-10-04 | C8: KMBK | D8: 2611N | E8: 45RE | F8: SD | G8: THLCH | H8: THLCH | I8: KRPUS | J8: KRPUS | K8: F | L8: ONE | M8: VFL | N8: LCH04 | O8: LCH | P8: TH | Q8: HASLS22260901847 | R8: N | S8: N | T8: KHS | V8: K0120025 | W8: GFPT PUBLIC COMPANY LIMITED | X8: VFD | Y8: TO THE ORDER OF WOORI BANK SEOUL | Z8: IATS CO.,LTD | AA8: 24000 | AB8: LCH04 | AC8: PUS05
A9: FSCU5894339 | B9: 2026-10-04 | C9: KMBK | D9: 2611N | E9: 45RE | F9: SD | G9: THLCH | H9: THLCH | I9: KRPUS | J9: KRPUS | K9: F | L9: L/T | M9: VFL | N9: LCH04 | O9: LCH | P9: TH | Q9: HASLS22260902145 | R9: N | S9: N | T9: KHS | V9: C0320021 | W9: KAONA POULTRY CO., LTD. | X9: VFD | Y9: TO THE ORDER OF INDUSTRIAL BANK OF | Z9: NEW ASIA CO.,LTD. | AA9: 24444 | AB9: LCH04 | AC9: PUS05
A10: FSCU5896429 | B10: 2026-10-04 | C10: KMBK | D10: 2611N | E10: 45RE | F10: SD | G10: THLCH | H10: THLCH | I10: KRPUS | J10: RUVVO | K10: F | L10: ONE | M10: VFL | N10: LCH04 | O10: LCH | P10: TH | Q10: HASLS22260902458 | R10: Y | S10: N | T10: KHS | V10: K0120025 | W10: VENTE TRADE CO.,LTD. | X10: VFD | Y10: JOINT-STOCK COMPANY "GRAND-TRADE" | Z10: NOURISH HUB FOOD AND BEVERAGES | AA10: 19554.5 | AB10: LCH04 | AC10: VVO01
A11: FSCU5910110 | B11: 2026-10-04 | C11: KMBK | D11: 2611N | E11: 45RE | F11: SD | G11: THLCH | H11: THLCH | I11: VNSGN | J11: VNSGN | K11: F | L11: L/T | M11: VFL | N11: LCH04 | O11: LCH | P11: TH | Q11: HASLS22260902138 | R11: N | S11: N | T11: KHS | V11: C0321002 | W11: UNITED MUSHROOM CENTER CO., LTD. | X11: VFD | Y11: VAN HUNG LONG INVESMENT TRADING | Z11: VAN HUNG LONG INVESMENT TRADING | AA11: 16059.5 | AB11: LCH04 | AC11: SGN03
A12: HALU2021929 | B12: 2026-10-04 | C12: KMBK | D12: 2611N | E12: 22GP | F12: SD | G12: THLCH | H12: THLCH | I12: VNSGN | J12: VNSGN | K12: F | L12: OWN | M12: VFL | N12: LCH04 | O12: LCH | P12: TH | Q12: HASLS22260902380 | R12: N | S12: N | T12: KHS | V12: TXG13016 | W12: WELLGROW GLASS INDUSTRY CO., LTD. | X12: VED | Y12: SAIGON COSMETICS CORPORATION | Z12: SAIGON COSMETICS CORPORATION | AA12: 12890 | AB12: LCH04 | AC12: SGN03
A13: HALU2045957 | B13: 2026-10-04 | C13: KMBK | D13: 2611N | E13: 22GP | F13: SD | G13: THLCH | H13: THLCH | I13: VNSGN | J13: VNSGN | K13: F | L13: ONE | M13: VFL | N13: LCH04 | O13: LCH | P13: TH | Q13: HASLS22260802191 | R13: N | S13: N | T13: KHS | V13: K0120021 | W13: THAI SYNTHETIC RUBBERS COMPANY | X13: VED | Y13: FULUH SHOES CO.,LTD | Z13: OIA GLOBAL VIETNAM CO., LTD | AA13: 17724 | AB13: LCH04 | AC13: SGN03
... A94: UETU2420663 | B94: 2026-10-04 | C94: KMBK | D94: 2611N | E94: 22GP | F94: SD | G94: THLCH | H94: THLCH | I94: KRUSN | J94: KRUSN | K94: F | L94: L/T | M94: VFL | N94: LCH04 | O94: LCH | P94: TH | Q94: HASLS22260900594 | R94: N | S94: N | T94: KHS | V94: TSN16L02 | W94: MJ LOGISTICS (THAILAND) CO.,LTD. | X94: VFD | Y94: YK LOGIS CO., LTD. | Z94: YK LOGIS CO., LTD. | AA94: 20110 | AB94: LCH04 | AC94: USN03

Sheet 2.Bookinglist
A1: B/K No | B1: Cntr Type & Size | C1: Pickup | D1: CY Return | E1: RCVCD | F1: C10 | G1: C20 | H1: C40 | I1: C45 | J1: TEU | K1: SOC | L1: SVC | M1: VSL | N1: VOY | O1: POL | P1: LWharf | Q1: LAREA | R1: ETD | S1: POD | T1: DWharf | U1: Delivery | V1: ETA | W1: DAREA | X1: Inland | Y1: T/S WHARF | Z1: TS PORT | AA1: Shipper | AB1: Org Shipper | AC1: BKG WGT | AD1: BK Tot Weight | AE1: Cntr Compare | AF1: SR | AG1: PKG | AH1: EL | AI1: CHK | AJ1: TRAFFIC | AK1: DocumentID | AL1: Document | AM1: SALESCD | AN1: SALESNM | AO1: Main Item | AP1: B/K Type | AQ1: DG | AR1: DGCNT | AS1: RF | AT1: RFCNT | AU1: AWK | AV1: AWKCNT | AW1: AWKVOID | AX1: FLEXIBAG | AY1: BLISSUE | AZ1: Remark | BA1: OFFICERMK | BB1: PAY TERM | BC1: Input Date | BD1: Update Date | BE1: Status | BF1: Commodity | BG1: Self Trans | BH1: Booking Loc | BI1: Trans Code | BJ1: Trans Name | BK1: Pickup | BL1: Pickup Date | BM1: 12GP | BN1: 22GP | BO1: 42GP | BP1: 45GP | BQ1: 22RE | BR1: 45RE | BS1: 22UT | BT1: 42UT | BU1: 22PC | BV1: 42PC | BW1: 22TN | BX1: 42TN | BY1: FE | BZ1: STAY | CA1: WEB | CB1: Special Remark | CC1: Return | CD1: Over WGT | CE1: VGM ERR MSG | CF1: CLASS(DG) TEU | CG1: CGO TERM | CH1: T/S Info | CI1: Email | CJ1: Shipper | CK1: Consignee | CL1: Notify | CM1: B/L Close | CN1: DOC_CLOSE | CO1: CNTR_CLOSE | CP1: Special Info. | CQ1: TARIFF REF | CR1: TARIFF CUSTOMER | CS1: TARIFF CUSTOMER NAME | CT1: Split | CU1: DG App Mail | CV1: Cas No. | CW1: CUST ETD | CX1: HSCODE | CY1: Roll Over Remark
A2: HASLS22260900886 | B2: 40Hx1 | C2: 1 | D2: 1 | F2: 0 | G2: 0 | H2: 0 | I2: 1 | J2: 2 | K2: N | L2: KHS1 | M2: KMBK | N2: 2611N | O2: THLCH | P2: LCH04 | Q2: IA | R2: 2026-10-04 | S2: RUVVO | T2: VVO01 | U2: RUVVO | V2: 2026-10-19 | W2: RU | Y2: PUS05 | Z2: KRPUS | AA2: ROHLIG (THAILAND) LIMITED | AB2: SSL MANUFACTURING (THAILAND) LTD. | AC2: 11462.038 | AD2: 15462.038 | AE2: OK | AH2: CHK | AI2: OK | AM2: TBKK13 | AN2: Dharaporn | AO2: LUBRICANT GEL (NON DG) | AP2: T/S | AW2: 0 | AX2: N | AY2: OBL | AZ2: [FIX][FIX]Pickup : 2026-09-28, Return : 2026-09-29 **CHECK OPENGATE BEFORE RETURN CNTR** | BA2: **DROP OFF AT MOSCOW** | BB2: P | BC2: 2026-09-10 | BD2: 2026-10-01 | BE2: Y | BF2: CONDOM | BG2: Line | BH2: S22 | BK2: LCHY5 | BL2: 2026-09-28 | BP2: 1 | BY2: FULL | BZ2: 5 | CA2: Y | CC2: LCH04 | CF2: 0 Teu | CG2: CY/CY | CH2: POL: THLCH [KMBK/2611N]; T/S(1st): KRPUS [SDTR/2629N]; POD: RUVVO [/] | CI2: TH.RC.BKK.SEA.BOOKING@ROHLIG.COM | CJ2: ROHLIG (THAILAND) LIMITED | CK2: RECKITT BENCKISER HEALTHCARE LLC | CL2: SUUS LOGISTICS LTD | CM2: CLOSED | CN2: 202610011700 | CO2: 202610022359 | CQ2: S22-2403023 | CR2: THTJ5I | CS2: ROHLIG (THAILAND) LIMITED | CT2: N | CW2: 2026-10-04 | CX2: 401410
A3: HASLS22260902143 | B3: R40Hx1 | C3: 1 | D3: 1 | F3: 0 | G3: 0 | H3: 0 | I3: 1 | J3: 2 | K3: N | L3: KHS1 | M3: KMBK | N3: 2611N | O3: THLCH | P3: LCH04 | Q3: IA | R3: 2026-10-04 | S3: KRPUS | T3: PUS05 | U3: KRPUS | V3: 2026-10-12 | W3: KR | AA3: MAXCORE LOGISTICS CO., LTD. | AB3: KAONA POULTRY CO., LTD. | AC3: 24444 | AD3: 28444 | AE3: OK | AH3: CHK | AI3: OK | AM3: TBKK19 | AN3: Kanokporn | AO3: FROZEN FRESH CHICKEN MEAT | AP3: Normal | AS3: RF// MIN:-19.0 MAX:-19.0 [COVER:CLOSE] | AT3: 45REx1 | AW3: 0 | AX3: N | AY3: OBL | AZ3: Pickup : 2026-09-24, Return : 2026-10-02 (Temp -19.0 / Vent Close) CLS TIME 03/10/26 @15.00 | BB3: P | BC3: 2026-09-23 | BD3: 2026-10-01 | BE3: Y | BF3: FROZEN CHICKEN MEAT | BG3: Line | BH3: S22 | BK3: LCH27 | BL3: 2026-09-24 | BR3: 1 | BY3: FULL | CA3: Y | CC3: LCH04 | CF3: 0 Teu | CG3: CY/CY | CI3: kae@maxcorelogistics.com | CJ3: KAONA POULTRY CO., LTD. | CK3: TO THE ORDER OF INDUSTRIAL BANK OF | CL3: NEW ASIA CO.,LTD. | CM3: CLOSED | CN3: 202610011700 | CO3: 202610022359 | CP3: 45RE x1: RF(Temp:-19.0' / Cover:CLOSE) | CQ3: S19-2003016 | CR3: THTHWY | CS3: MAXCORE LOGISTICS CO., LTD. | CT3: N | CW3: 2026-10-04
A4: HASLS22260901848 | B4: R40Hx1 | C4: 1 | D4: 1 | F4: 0 | G4: 0 | H4: 0 | I4: 1 | J4: 2 | K4: N | L4: KHS1 | M4: KMBK | N4: 2611N | O4: THLCH | P4: LCH04 | Q4: IA | R4: 2026-10-04 | S4: KRPUS | T4: PUS05 | U4: KRPUS | V4: 2026-10-12 | W4: KR | AA4: GFPT PUBLIC COMPANY LIMITED. | AB4: GFPT PUBLIC COMPANY LIMITED. | AC4: 24000 | AD4: 28000 | AE4: OK | AF4: SR | AH4: CHK | AI4: OK | AM4: TH0011 | AN4: Nannaapust Sukporntaweewat | AO4: FROZEN CHICKEN MIDDLE WING 30-45G. | AP4: Normal | AS4: RF// MIN:-20 MAX:-20 [COVER:CLOSE] | AT4: 45REx1 | AW4: 0 | AX4: N | AY4: OBL | AZ4: CY - RTN DD: 30-01/10/26 (TEMP : -20'C / VENT CLOSE) CLS TIME 02/10/26 @12.00 (1ST RETURN 02/10/26) | BB4: P | BC4: 2026-09-21 | BD4: 2026-09-30 | BE4: Y | BF4: FROZEN CHICEKN | BG4: Line | BH4: S22 | BK4: BKK27 | BL4: 2026-09-30 | BR4: 1 | BY4: FULL | CC4: LCH04 | CF4: 0 Teu | CG4: CY/CY | CI4: kanokchol-kadi@gfpt.co.th | CJ4: GFPT PUBLIC COMPANY LIMITED | CK4: TO THE ORDER OF WOORI BANK SEOUL | CL4: IATS CO.,LTD | CM4: CLOSED | CN4: 202610011700 | CO4: 202610022359 | CP4: 45RE x1: RF(Temp:-20' / Cover:CLOSE) | CQ4: S22-2306014 | CR4: X0880 | CS4: GFPT PUBLIC COMPANY LIMITED. | CT4: N | CW4: 2026-10-03
A5: HASLS22260901768 | B5: R40Hx1 | C5: 1 | D5: 1 | F5: 0 | G5: 0 | H5: 0 | I5: 1 | J5: 2 | K5: N | L5: KHS1 | M5: KMBK | N5: 2611N | O5: THLCH | P5: LCH04 | Q5: IA | R5: 2026-10-04 | S5: VNSGN | T5: SGN03 | U5: VNSGN | V5: 2026-10-06 | W5: IA | AA5: GOLDEN SEA FROZEN FOODS CO.,LTD | AB5: GOLDEN SEA FROZEN FOODS CO.,LTD | AC5: 27666 | AD5: 31666 | AE5: OK | AH5: CHK | AM5: TBKK19 | AN5: Kanokporn | AO5: FROZEN SOFT CUTTLEFISH | AP5: Normal | AS5: RF// MIN:-18.0 MAX:-18.0 [COVER:CLOSE] | AT5: 45REx1 | AW5: 0 | AX5: N | AZ5: Pickup : 2026-09-26, Return : 2026-10-01 (Temp -18.0 / Vent Close) CLS TIME 02/10/26 @23.59 | BA5: SI DD.1/10/96 | BB5: P | BC5: 2026-09-19 | BD5: 2026-10-02 | BE5: Y | BF5: FROZEN FISH | BG5: Line | BH5: S22 | BK5: LCH27 | BL5: 2026-09-26 | BR5: 1 | BY5: FULL | CA5: Y | CC5: LCH04 | CF5: 0 Teu | CG5: CY/CY | CI5: gsf.goldensea@gmail.com | CJ5: GOLDEN SEA FROZEN FOODS CO.,LTD. | CK5: KHANH LAN SEAFOOD IMPORT & EXPORT | CL5: KHANH LAN SEAFOOD IMPORT & EXPORT | CN5: 202610011700 | CO5: 202610022359 | CP5: 45RE x1: RF(Temp:-18.0' / Cover:CLOSE) | CQ5: S22-2507029 | CR5: THTXYN | CS5: GOLDEN SEA FROZEN FOODS CO.,LTD | CT5: N | CW5: 2026-10-04 | CX5: 030743
A6: HASLS22260901282 | B6: R40Hx1 | C6: 1 | D6: 1 | F6: 0 | G6: 0 | H6: 0 | I6: 1 | J6: 2 | K6: N | L6: KHS1 | M6: KMBK | N6: 2611N | O6: THLCH | P6: LCH04 | Q6: IA | R6: 2026-10-04 | S6: JPSDJ | T6: SDJ01 | U6: JPSDJ | V6: 2026-10-23 | W6: JP | Y6: PUS05 | Z6: KRPUS | AA6: KODAI (THAILAND) CO., LTD. | AB6: MCKEY FOOD SERVICES | AC6: 25479.09 | AD6: 29479.09 | AE6: OK | AH6: CON | AI6: OK | AM6: JTYO08 | AN6: Takatsugu Nakagome(Mr.) | AO6: FROZEN CHICKEN | AP6: T/S | AS6: RF// MIN:-25.0 MAX:-25.0 [COVER:CLOSE] | AT6: 45REx1 | AW6: 0 | AX6: N | AY6: OBL | AZ6: [FIX][FIX][FIX][FIX]Pickup : 2026-09-23, Return : 2026-09-29 (Temp -25.0 / Vent Close) *PRECOOL* CLS TIME 02/10/26 @23.59 COST PRECOOL = 1,200 BAHT | BA6: COST PRECOOL = 1,200 BAHT | BB6: C | BC6: 2026-09-15 | BD6: 2026-10-01 | BE6: Y | BF6: FROZEN CHICKEN | BG6: Line | BH6: S22 | BK6: LCH27 | BL6: 2026-09-23 | BR6: 1 | BY6: FULL | BZ6: 6 | CA6: Y | CC6: LCH04 | CF6: 0 Teu | CG6: CY/CY | CH6: POL: THLCH [KMBK/2611N]; T/S(1st): KRPUS [HAHP/2638E]; POD: JPSDJ [/] | CI6: support@kodai-thailand.co.th | CJ6: KODAI (THAILAND) CO., LTD. | CK6: KODAI COMPANY LTD. | CL6: KODAI COMPANY LTD. | CM6: CLOSED | CN6: 202610011700 | CO6: 202610022359 | CP6: 45RE x1: RF(Temp:-25.0' / Cover:CLOSE) | CQ6: TYO16A0065-1 | CR6: THTJMC | CS6: KODAI (THAILAND) CO., LTD. | CT6: N | CW6: 2026-10-03 | CX6: 160232
A7: HASLS22260901278 | B7: R40Hx1 | C7: 1 | D7: 1 | F7: 0 | G7: 0 | H7: 0 | I7: 1 | J7: 2 | K7: N | L7: KHS1 | M7: KMBK | N7: 2611N | O7: THLCH | P7: LCH04 | Q7: IA | R7: 2026-10-04 | S7: JPISS | T7: ISS02 | U7: JPISS | V7: 2026-10-24 | W7: JP | Y7: PUS05 | Z7: KRPUS | AA7: KODAI (THAILAND) CO., LTD. | AB7: MCKEY FOOD SERVICES | AC7: 25479.09 | AD7: 29479.09 | AE7: OK | AH7: CON | AI7: OK | AM7: JTYO08 | AN7: Takatsugu Nakagome(Mr.) | AO7: FROZEN CHICKEN | AP7: T/S | AS7: RF// MIN:-25.0 MAX:-25.0 [COVER:CLOSE] | AT7: 45REx1 | AW7: 0 | AX7: N | AY7: OBL | AZ7: Pickup : 2026-09-23, Return : 2026-09-29 (Temp -25.0 / Vent Close) CLS TIME 03/10 @ 07.00 | BB7: C | BC7: 2026-09-15 | BD7: 2026-10-01 | BE7: Y | BF7: FROZEN CHICKEN | BG7: Line | BH7: S22 | BK7: LCH27 | BL7: 2026-09-23 | BR7: 1 | BY7: FULL | BZ7: 9 | CA7: Y | CC7: LCH04 | CF7: 0 Teu | CG7: CY/CY | CH7: POL: THLCH [KMBK/2611N]; T/S(1st): KRPUS [HAKT/2637E]; POD: JPISS [/] | CI7: support@kodai-thailand.co.th | CJ7: KODAI (THAILAND) CO., LTD. | CK7: KODAI COMPANY LTD. | CL7: KODAI COMPANY LTD. | CM7: CLOSED | CN7: 202610011700 | CO7: 202610022359 | CP7: 45RE x1: RF(Temp:-25.0' / Cover:CLOSE) | CQ7: TYO16A0065-1 | CR7: THTJMC | CS7: KODAI (THAILAND) CO., LTD. | CT7: N | CW7: 2026-10-03 | CX7: 160232
A8: HASLS22260901847 | B8: R40Hx1 | C8: 1 | D8: 1 | F8: 0 | G8: 0 | H8: 0 | I8: 1 | J8: 2 | K8: N | L8: KHS1 | M8: KMBK | N8: 2611N | O8: THLCH | P8: LCH04 | Q8: IA | R8: 2026-10-04 | S8: KRPUS | T8: PUS05 | U8: KRPUS | V8: 2026-10-12 | W8: KR | AA8: GFPT PUBLIC COMPANY LIMITED. | AB8: GFPT PUBLIC COMPANY LIMITED. | AC8: 24000 | AD8: 28000 | AE8: OK | AF8: SR | AH8: CHK | AI8: OK | AM8: TH0011 | AN8: Nannaapust Sukporntaweewat | AO8: FROZEN CHICKEN WING STICK 40-55G. | AP8: Normal | AS8: RF// MIN:-20 MAX:-20 [COVER:CLOSE] | AT8: 45REx1 | AW8: 0 | AX8: N | AY8: OBL | AZ8: CY - RTN DD: 30-01/10/26 (TEMP : -20'C / VENT CLOSE) CLS TIME 03/10/26 @09.00 (1ST RETURN 02/10/26) | BB8: P | BC8: 2026-09-21 | BD8: 2026-10-01 | BE8: Y | BF8: FROZEN CHICEKN | BG8: Line | BH8: S22 | BK8: BKK27 | BL8: 2026-09-30 | BR8: 1 | BY8: FULL | CC8: LCH04 | CF8: 0 Teu | CG8: CY/CY | CI8: kanokchol-kadi@gfpt.co.th | CJ8: GFPT PUBLIC COMPANY LIMITED | CK8: TO THE ORDER OF WOORI BANK SEOUL | CL8: IATS CO.,LTD | CM8: CLOSED | CN8: 202610011700 | CO8: 202610022359 | CP8: 45RE x1: RF(Temp:-20' / Cover:CLOSE) | CQ8: S22-2306014 | CR8: X0880 | CS8: GFPT PUBLIC COMPANY LIMITED. | CT8: N | CW8: 2026-10-03
A9: HASLS22260902145 | B9: R40Hx1 | C9: 1 | D9: 1 | F9: 0 | G9: 0 | H9: 0 | I9: 1 | J9: 2 | K9: N | L9: KHS1 | M9: KMBK | N9: 2611N | O9: THLCH | P9: LCH04 | Q9: IA | R9: 2026-10-04 | S9: KRPUS | T9: PUS05 | U9: KRPUS | V9: 2026-10-12 | W9: KR | AA9: MAXCORE LOGISTICS CO., LTD. | AB9: KAONA POULTRY CO., LTD. | AC9: 24444 | AD9: 28444 | AE9: OK | AH9: CHK | AI9: OK | AM9: TBKK19 | AN9: Kanokporn | AO9: FROZEN FRESH CHICKEN MEAT | AP9: Normal | AS9: RF// MIN:-19.0 MAX:-19.0 [COVER:CLOSE] | AT9: 45REx1 | AW9: 0 | AX9: N | AY9: OBL | AZ9: Pickup : 2026-09-24, Return : 2026-10-02 (Temp -19.0 / Vent Close) CLS TIME 03/10/26 @15.00 | BB9: P | BC9: 2026-09-23 | BD9: 2026-10-01 | BE9: Y | BF9: FROZEN CHICKEN MEAT | BG9: Line | BH9: S22 | BK9: LCH27 | BL9: 2026-09-24 | BR9: 1 | BY9: FULL | CA9: Y | CC9: LCH04 | CF9: 0 Teu | CG9: CY/CY | CI9: kae@maxcorelogistics.com | CJ9: KAONA POULTRY CO., LTD. | CK9: TO THE ORDER OF INDUSTRIAL BANK OF | CL9: NEW ASIA CO.,LTD. | CM9: CLOSED | CN9: 202610011700 | CO9: 202610022359 | CP9: 45RE x1: RF(Temp:-19.0' / Cover:CLOSE) | CQ9: S19-2003016 | CR9: THTHWY | CS9: MAXCORE LOGISTICS CO., LTD. | CT9: N | CW9: 2026-10-04
A10: HASLS22260902458 | B10: R40Hx2 | C10: 2 | D10: 2 | F10: 0 | G10: 0 | H10: 0 | I10: 2 | J10: 4 | K10: N | L10: KHS1 | M10: KMBK | N10: 2611N | O10: THLCH | P10: LCH04 | Q10: IA | R10: 2026-10-04 | S10: RUVVO | T10: VVO01 | U10: RUVVO | V10: 2026-10-14 | W10: RU | Y10: PUS05 | Z10: KRPUS | AA10: VENTE TRADE CO.,LTD. | AB10: VENTE TRADE CO.,LTD. | AC10: 39828.59 | AD10: 47828.59 | AE10: OK | AH10: CHK | AI10: OK | AM10: RUVO17 | AN10: Insuk Heo | AO10: CANNED PINEAPPLE CHUNKS IN JUICE | AP10: Normal | AS10: RF// MIN:+10.0 MAX:+10.0 [COVER:CLOSE] | AT10: 45REx2 | AW10: 0 | AX10: N | AY10: OBL | AZ10: [FIX][FIX][FIX]CY-RTN :30-02/10/2026 (TEMP : +10'C / VENT CLOSE) CLS TIME DD.03/10/2026 @ 12.00 *1ST RETURN CNTR DD.02/10/2026 WITHOUT CHARGE* ORDER : GT-744673, GT-756813 | BA10: SI DD.1/10/26 | BB10: C | BC10: 2026-09-25 | BD10: 2026-10-01 | BE10: Y | BF10: CANNED FRUIT | BG10: Line | BH10: S22 | BK10: LCH27 | BL10: 2026-09-29 | BR10: 2 | BY10: FULL | BZ10: 0 | CC10: LCH04 | CF10: 0 Teu | CG10: CY/CY | CH10: POL: THLCH [KMBK/2611N]; T/S(1st): KRPUS [SWTD/9017N]; POD: RUVVO [/] | CI10: document1@vente.co.th | CJ10: VENTE TRADE CO.,LTD. | CK10: JOINT-STOCK COMPANY "GRAND-TRADE" | CL10: NOURISH HUB FOOD AND BEVERAGES | CM10: CLOSED | CN10: 202610011700 | CO10: 202610022359 | CP10: 45RE x2: RF(Temp:+10.0' / Cover:CLOSE) | CQ10: R01-2604022 | CR10: THTI5U | CS10: VENTE TRADE CO.,LTD. | CT10: N | CW10: 2026-10-04 | CX10: 200820
A11: HASLS22260902138 | B11: R40Hx1 | C11: 1 | D11: 1 | F11: 0 | G11: 0 | H11: 0 | I11: 1 | J11: 2 | K11: N | L11: KHS1 | M11: KMBK | N11: 2611N | O11: THLCH | P11: LCH04 | Q11: IA | R11: 2026-10-04 | S11: VNSGN | T11: SGN03 | U11: VNSGN | V11: 2026-10-06 | W11: IA | AA11: FOCUS FREIGHT & LOGISTICS CO., LTD. | AB11: UNITED MUSHROOM CENTER CO., LTD. | AC11: 16059.5 | AD11: 20059.5 | AE11: OK | AF11: SR | AH11: CHK | AI11: OK | AM11: TBKK13 | AN11: Dharaporn | AO11: GOLDEN MUSHROOM | AP11: Normal | AS11: RF// MIN:+0.0 MAX:+0.0 [COVER:CLOSE] | AT11: 45REx1 | AW11: 0 | AX11: N | AZ11: Pickup : 2026-09-30, Return : 2026-10-02 (Temp +0.0 / Vent Close) CLS TIME 03/10/26 @15.00 | BA11: REQ CLEAN & GOOD CONTAINER FOR FOODS | BB11: P | BC11: 2026-09-23 | BD11: 2026-09-30 | BE11: Y | BF11: GOLDEN MUSHROOM | BG11: Line | BH11: S22 | BK11: LCH27 | BL11: 2026-09-30 | BR11: 1 | BY11: FULL | CA11: Y | CC11: LCH04 | CF11: 0 Teu | CG11: CY/CY | CI11: CSDEP@FOCUS-FREIGHT.CO.TH | CJ11: UNITED MUSHROOM CENTER CO., LTD. | CK11: VAN HUNG LONG INVESMENT TRADING | CL11: VAN HUNG LONG INVESMENT TRADING | CN11: 202610011700 | CO11: 202610022359 | CP11: 45RE x1: RF(Temp:+0.0' / Cover:CLOSE) | CQ11: S22-2411025 | CR11: TH0059 | CS11: FOCUS FREIGHT & LOGISTICS CO., LTD. | CT11: N | CW11: 2026-10-04 | CX11: 070959
A12: HASLS22260902380 | B12: 20'x1 | C12: 1 | D12: 1 | F12: 0 | G12: 1 | H12: 0 | I12: 0 | J12: 1 | K12: N | L12: KHS1 | M12: KMBK | N12: 2611N | O12: THLCH | P12: LCH04 | Q12: IA | R12: 2026-10-04 | S12: VNSGN | T12: SGN03 | U12: VNSGN | V12: 2026-10-06 | W12: IA | AA12: UNITED MARINE LOGISTIC CO., LTD. | AB12: WELLGROW GLASS INDUSTRY CO., LTD. | AC12: 12890 | AD12: 15090 | AE12: OK | AH12: CHK | AI12: OK | AM12: TH0011 | AN12: Nannaapust Sukporntaweewat | AO12: GLASS BOTTLE | AP12: Normal | AW12: 0 | AX12: N | AZ12: Pickup : 2026-09-29, Return : 2026-09-30 | BB12: P | BC12: 2026-09-25 | BD12: 2026-10-01 | BE12: Y | BF12: GLASS BOTTLE | BG12: Line | BH12: S22 | BK12: LCHY5 | BL12: 2026-09-29 | BN12: 1 | BY12: FULL | CA12: Y | CC12: LCH04 | CF12: 0 Teu | CG12: CY/CY | CI12: customer@umac.co.th | CJ12: WELLGROW GLASS INDUSTRY CO., LTD. | CK12: SAIGON COSMETICS CORPORATION | CL12: SAIGON COSMETICS CORPORATION | CN12: 202610011700 | CO12: 202610022359 | CQ12: S22-2406015 | CR12: BB1277 | CS12: UNITED MARINE LOGISTIC CO., LTD. | CT12: N | CW12: 2026-10-04 | CX12: 701090
A13: HASLS22260802191 | B13: 20'x2 | C13: 2 | D13: 2 | F13: 0 | G13: 2 | H13: 0 | I13: 0 | J13: 2 | K13: N | L13: KHS1 | M13: KMBK | N13: 2611N | O13: THLCH | P13: LCH04 | Q13: IA | R13: 2026-10-04 | S13: VNSGN | T13: SGN03 | U13: VNSGN | V13: 2026-10-06 | W13: IA | AA13: UBE CHEMICALS (ASIA) PUBLIC COMPANY LIMITED | AB13: THAI SYNTHETIC RUBBERS CO., LTD. | AC13: 35448 | AD13: 39848 | AE13: OK | AH13: CHK | AI13: OK | AM13: TBKK47 | AN13: Tarn(Supaporn) | AO13: POLYBUTADIENE RUBBER UBEPOL | AP13: Normal | AW13: 0 | AX13: N | AZ13: CY-RTN : 28-29/09/26 (ID-N016385) ** PLEASE CHECK OPEN GATE BEFORE RETURN CONTAINER ** | BA13: SI DD.29/9/26 FM SWSP 2609N DD.23/09 | BB13: P | BC13: 2026-08-26 | BD13: 2026-10-01 | BE13: Y | BF13: RUBBER | BG13: Line | BH13: S22 | BK13: LCHY5 | BL13: 2026-09-28 | BN13: 2 | BY13: FULL | CC13: LCH04 | CF13: 0 Teu | CG13: CY/CY | CI13: nunnaphus@ube.co.th;ugttransportex@ube.co.th | CJ13: THAI SYNTHETIC RUBBERS COMPANY | CK13: FULUH SHOES CO.,LTD | CL13: OIA GLOBAL VIETNAM CO., LTD | CN13: 202610011700 | CO13: 202610022359 | CQ13: S22-2211002 | CR13: TH035E | CS13: UBE CHEMICALS (ASIA) PUBLIC COMPANY LIMITED | CT13: N | CW13: 2026-10-04 | CX13: 400220
A14: HASLS22260902002 | B14: 20'x7 | C14: 7 | D14: 7 | F14: 0 | G14: 7 | H14: 0 | I14: 0 | J14: 7 | K14: N | L14: KHS1 | M14: KMBK | N14: 2611N | O14: THLCH | P14: LCH04 | Q14: IA | R14: 2026-10-04 | S14: VNSGN | T14: SGN03 | U14: VNSGN | V14: 2026-10-06 | W14: IA | AA14: EVERGREEN LOGISTICS (THAILAND) CO., LTD. | AB14: T.C.PHARMACEUTICAL INDUSTRIES CO., LTD. | AC14: 138841.92 | AD14: 154241.92 | AE14: OK | AH14: CHK | AI14: OK | AM14: TH0031 | AN14: Pattarapong Saengthong | AO14: ENERGY DRINK | AP14: Normal | AW14: 0 | AX14: N | AZ14: Pickup : 2026-09-29, Return : 2026-09-30 | BB14: P | BC14: 2026-09-22 | BD14: 2026-10-01 | BE14: Y | BF14: ENERGY DRINK | BG14: Line | BH14: S22 | BK14: LCHY5 | BL14: 2026-09-29 | BN14: 7 | BY14: FULL | CA14: Y | CC14: LCH04 | CF14: 0 Teu | CG14: CY/CY | CI14: pongsakorn@th.evergreen-logistics.com | CJ14: T.C. PHARMACEUTICAL INDUSTRIES | CK14: TCPVN COMPANY LIMITED | CL14: TCPVN COMPANY LIMITED | CN14: 202610011700 | CO14: 202610022359 | CQ14: S22-2607001 | CR14: TH01G9 | CS14: EVERGREEN LOGISTICS (THAILAND) CO., LTD. | CT14: N | CW14: 2026-10-04 | CX14: 220210
A15: HASLS22260900415 | B15: 20'x1 | C15: 1 | D15: 1 | F15: 0 | G15: 1 | H15: 0 | I15: 0 | J15: 1 | K15: N | L15: KHS1 | M15: KMBK | N15: 2611N | O15: THLCH | P15: LCH04 | Q15: IA | R15: 2026-10-04 | S15: VNSGN | T15: SGN03 | U15: VNSGN | V15: 2026-10-06 | W15: IA | AA15: STAR CONCORD (THAILAND) CO., LTD. | AB15: SIAM COATED ABRASIVE CO., LTD. | AC15: 8432 | AD15: 10632 | AE15: OK | AH15: CHK | AI15: OK | AM15: TBKK97 | AN15: Arunphat W. (Aiw) | AO15: ABRASIVE CLOTH ROLL | AP15: Normal | AW15: 0 | AX15: N | AZ15: Pickup : 2026-09-29, Return : 2026-09-30 | BB15: P | BC15: 2026-09-04 | BD15: 2026-09-29 | BE15: Y | BF15: ABRASIVE CLOTH ROLL | BG15: Line | BH15: S22 | BK15: LCH27 | BL15: 2026-09-29 | BN15: 1 | BY15: FULL | CA15: Y | CC15: LCH04 | CF15: 0 Teu | CG15: CY/CY | CI15: wilawan.kh@starconcord.co.th | CJ15: STAR CONCORD (THAILAND) CO., LTD. | CK15: STAR CONCORD (VIETNAM) CO., LTD. | CL15: STAR CONCORD (VIETNAM) CO., LTD. | CN15: 202610011700 | CO15: 202610022359 | CQ15: S19-1912005 | CR15: THTIYM | CS15: STAR CONCORD (THAILAND) CO., LTD. | CT15: N | CW15: 2026-10-01 | CX15: 680510
A16: HASLS22260900594 | B16: 20'x3 | C16: 3 | D16: 3 | F16: 0 | G16: 3 | H16: 0 | I16: 0 | J16: 3 | K16: N | L16: KHS1 | M16: KMBK | N16: 2611N | O16: THLCH | P16: LCH04 | Q16: IA | R16: 2026-10-04 | S16: KRUSN | T16: USN03 | U16: KRUSN | V16: 2026-10-13 | W16: KR | AA16: MJ LOGISTICS (THAILAND) CO., LTD. | AB16: INTER RUBBER LATEX CO., LTD. | AC16: 60330 | AD16: 66930 | AE16: OK | AH16: CON | AI16: OK | AM16: 96031 | AN16: HA MAN KI | AO16: NATURAL RUBBER LATEX | AP16: Normal | AW16: 0 | AX16: Y | AY16: OBL | AZ16: *APPROVAL BY MR.JEONG-YOUNG UM DD.10/09/2026** *flexibag ondeck* Servey 2026-09-18 ,Pickup : 2026-09-19, Return : 2026-09-28 | BB16: C | BC16: 2026-09-07 | BD16: 2026-09-30 | BE16: Y | BF16: LATEX 60% | BG16: Line | BH16: S22 | BK16: LCHY5 | BL16: 2026-09-18 | BN16: 3 | BY16: FULL | CA16: Y | CC16: LCH04 | CF16: 0 Teu | CG16: CY/CY | CI16: seaexp1@mjlog.co.th | CJ16: MJ LOGISTICS (THAILAND) CO.,LTD. | CK16: YK LOGIS CO., LTD. | CL16: YK LOGIS CO., LTD. | CM16: CLOSED | CN16: 202610011700 | CO16: 202610022359 | CQ16: K02-2403031 | CR16: THTKFU | CS16: MJ LOGISTICS (THAILAND) CO., LTD. | CT16: N | CW16: 2026-10-02
A17: HASLS22260901498 | B17: 20'x5 | C17: 5 | D17: 5 | F17: 0 | G17: 5 | H17: 0 | I17: 0 | J17: 5 | K17: N | L17: KHS1 | M17: KMBK | N17: 2611N | O17: THLCH | P17: LCH04 | Q17: IA | R17: 2026-10-04 | S17: JPISS | T17: ISS02 | U17: JPISS | V17: 2026-10-24 | W17: JP | Y17: PUS05 | Z17: KRPUS | AA17: HAST LOGISTICS CO., LTD. | AB17: TPT PETROCHEMICALS PUBLIC COMPANY LIMITED | AC17: 106090 | AD17: 117090 | AE17: OK | AH17: CHK | AI17: OK | AM17: TBKK19 | AN17: Kanokporn | AO17: PET RESIN RAMAPET N1 | AP17: T/S | AW17: 0 | AX17: N | AY17: OBL | AZ17: Pickup : 2026-09-23, Return : 2026-09-25 **CHECK OPENGATE BEFORE RETURN CNTR** | BA17: ROLL OVER FROM PREVIOUS VSL SWAL 2608N BY ALLOCATION TEAM MS.TARN APRPOVED COST IS UNDER HA DD.27/09 | BB17: P | BC17: 2026-09-17 | BD17: 2026-09-29 | BE17: Y | BF17: PET RESIN | BG17: Line | BH17: S22 | BK17: LCH27 | BL17: 2026-09-23 | BN17: 5 | BY17: FULL | BZ17: 9 | CA17: Y | CC17: LCH04 | CF17: 0 Teu | CG17: CY/CY | CH17: POL: THLCH [KMBK/2611N]; T/S(1st): KRPUS [HAKT/2637E]; POD: JPISS [/] | CI17: cs@hast.co.th | CJ17: TPT PETROCHEMICALS PUBLIC COMPANY | CK17: IWATANI CORPORATION | CL17: IWATANI CORPORATION | CM17: CLOSED | CN17: 202610011700 | CO17: 202610022359 | CQ17: BKK14A0215-1 | CR17: THTHBP | CS17: HAST LOGISTICS CO., LTD. | CT17: N | CW17: 2026-10-04 | CX17: 390761 | CY17: ROLL OVER FROM PREVIOUS VSL SWAL 2608N BY ALLOCATION TEAM MS.TARN APRPOVED COST IS UNDER HA DD.27/09
A18: HASLS22260900719 | B18: 20'x3 | C18: 3 | D18: 3 | F18: 0 | G18: 3 | H18: 0 | I18: 0 | J18: 3 | K18: N | L18: KHS1 | M18: KMBK | N18: 2611N | O18: THLCH | P18: LCH04 | Q18: IA | R18: 2026-10-04 | S18: VNSGN | T18: SGN03 | U18: VNSGN | V18: 2026-10-06 | W18: IA | AA18: FAIR AND FAST COMPANY LIMITED | AB18: PACIFIC SUGAR CORPORATION LIMITED | AC18: 75255 | AD18: 81855 | AE18: OK | AF18: SR | AH18: CHK | AM18: TBKK47 | AN18: Tarn(Supaporn) | AO18: SUGAR | AP18: Normal | AW18: 0 | AX18: N | AZ18: Pickup : 2026-09-28, Return : 2026-09-29 (1ST RTN 30/09 W/O RENT) ** PLEASE CHECK OPEN GATE BEFORE RETURN CNTR ** | BA18: FM SWSP 2609N 22/09REQUEST GOOD AND CLEAN CONTAINER FOR FOOD | BB18: P | BC18: 2026-09-09 | BD18: 2026-09-30 | BE18: Y | BF18: Sugar | BG18: Line | BH18: S22 | BK18: LCH27 | BL18: 2026-09-28 | BN18: 3 | BY18: FULL | CA18: Y | CC18: LCH04 | CF18: 0 Teu | CG18: CY/CY | CI18: FF-Freight@fairfast.co.th | CJ18: PACIFIC SUGAR CORPORATION LIMITED | CK18: TO ORDER | CL18: VIETFARM FOOD JOINT STOCK COMPANY | CN18: 202610011700 | CO18: 202610022359 | CQ18: BKK16A0258-1 | CR18: THTRVA | CS18: FAIR AND FAST COMPANY LIMITED | CT18: N | CW18: 2026-10-04 | CX18: 170199
A19: HASLS22260902075 | B19: 20'x3 | C19: 3 | D19: 3 | F19: 0 | G19: 3 | H19: 0 | I19: 0 | J19: 3 | K19: N | L19: KHS1 | M19: KMBK | N19: 2611N | O19: THLCH | P19: LCH04 | Q19: IA | R19: 2026-10-04 | S19: VNSGN | T19: SGN03 | U19: VNSGN | V19: 2026-10-06 | W19: IA | AA19: WHA GC LOGISTICS COMPANY LIMITED | AB19: PTT GLOBAL CHEMICAL PUBLIC COMPANY LIMITED | AC19: 54324 | AD19: 60924 | AE19: OK | AH19: CHK | AI19: OK | AM19: TBKK13 | AN19: Dharaporn | AO19: HIGH DENSITY POLYETHYLENE | AP19: Normal | AW19: 0 | AX19: N | AZ19: CY-RTN 18-21/09/26 *PLS CHECK OPEN GATE BEFORE RETURN CTNR* | BA19: SI DD.28/9/26 SKLU1616965 / HAL458725 MOVE FM BKG : HASLS22260900928 | BB19: P | BC19: 2026-09-23 | BD19: 2026-09-30 | BE19: Y | BF19: RESIN | BG19: Line | BH19: S22 | BK19: LCH27 | BL19: 2026-09-18 | BN19: 3 | BY19: FULL | CC19: LCH04 | CF19: 0 Teu | CG19: CY/CY | CI19: warayu.p@wha-gc.com | CJ19: PTT GLOBAL CHEMICAL PUBLIC COMPANY | CK19: TO THE ORDER OF JOINT STOCK | CL19: MIDA PRECISION MOLD CORP | CN19: 202610011700 | CO19: 202610022359 | CQ19: S22-2309036 | CR19: TH02GR | CS19: WHA GC LOGISTICS COMPANY LIMITED | CT19: N | CW19: 2026-09-27 | CX19: 390120
A20: HASLS22260802086 | B20: 20'x3 | C20: 3 | D20: 3 | F20: 0 | G20: 3 | H20: 0 | I20: 0 | J20: 3 | K20: N | L20: KHS1 | M20: KMBK | N20: 2611N | O20: THLCH | P20: LCH04 | Q20: IA | R20: 2026-10-04 | S20: KRPUS | T20: PUS05 | U20: KRPUS | V20: 2026-10-12 | W20: KR | AA20: MJ LOGISTICS (THAILAND) CO., LTD. | AB20: UNITEX RUBBER CO.,LTD | AC20: 60300 | AD20: 66900 | AE20: OK | AF20: SR | AH20: CON | AM20: 96031 | AN20: HA MAN KI | AO20: NATURAL RUBBER LATEX HIGH | AP20: Normal | AW20: 0 | AX20: Y | AZ20: **APPROVED BY JEONG YONG UM DD.29/09/26** *FLEXIBAG ONDECK* Servey 2026-09-18 , Pickup : 2026-09-19, Return : 2026-09-20 | BA20: ROLL OVER FROM PREVIOUS VSL SWIC 2610N BY ALLOCATION TEAM MS.TARN APRPOVED COST IS UNDER HA DD.21/09 REQ. SURVEN 14-SEPSC NO. K02-2403031 FM POD: KRUSN DD.29/09/26 HV LOI | BB20: C | BC20: 2026-08-25 | BD20: 2026-09-30 | BE20: Y | BF20: LATEX 60% | BG20: Line | BH20: S22 | BK20: LCH27 | BL20: 2026-09-18 | BN20: 3 | BY20: FULL | CA20: Y | CC20: LCH04 | CF20: 0 Teu | CG20: CY/CY | CI20: seaexp1@mjlog.co.th | CJ20: MJ LOGISTICS (THAILAND) CO.,LTD. | CK20: YK LOGIS CO., LTD. | CL20: YK LOGIS CO., LTD. | CN20: 202610011700 | CO20: 202610022359 | CQ20: K02-2403031 | CR20: THTKFU | CS20: MJ LOGISTICS (THAILAND) CO., LTD. | CT20: N | CW20: 2026-10-04 | CY20: ROLL OVER FROM PREVIOUS VSL SWIC 2610N BY ALLOCATION TEAM MS.TARN APRPOVED COST IS UNDER HA DD.21/09
A21: HASLS22260901863 | B21: 20'x3 | C21: 3 | D21: 3 | F21: 0 | G21: 3 | H21: 0 | I21: 0 | J21: 3 | K21: N | L21: KHS1 | M21: KMBK | N21: 2611N | O21: THLCH | P21: LCH04 | Q21: IA | R21: 2026-10-04 | S21: VNSGN | T21: SGN03 | U21: VNSGN | V21: 2026-10-06 | W21: IA | AA21: IRPC PUBLIC COMPANY LIMITED | AB21: IRPC PUBLIC COMPANY LIMITED | AC21: 49797 | AD21: 56397 | AE21: OK | AF21: SR | AH21: CHK | AI21: OK | AM21: TBKK13 | AN21: Dharaporn | AO21: POLYPROPYLENE RESIN | AP21: Normal | AW21: 0 | AX21: N | AZ21: CY-RTN 24-26/09/26 (S-IREX263442) *PLS CHECK OPEN GATE BEFORE RETURN CTNR* | BB21: P | BC21: 2026-09-21 | BD21: 2026-09-30 | BE21: Y | BF21: RESIN | BG21: Line | BH21: S22 | BK21: LCHY5 | BL21: 2026-09-24 | BN21: 3 | BY21: FULL | CC21: LCH04 | CF21: 0 Teu | CG21: CY/CY | CI21: anusara.k@irpc.co.th | CJ21: IRPC PUBLIC COMPANY LIMITED. | CK21: TO ORDER OF TECHCOMBANK-CHO LON | CL21: CONG TY TNHH SX TM NHUA MINH LONG | CN21: 202610011700 | CO21: 202610022359 | CQ21: S22-2603014 | CR21: BB0062 | CS21: IRPC PUBLIC COMPANY LIMITED | CT21: N | CW21: 2026-10-03 | CX21: 390210
A22: HASLS22260900666 | B22: 20'x3 | C22: 3 | D22: 3 | F22: 0 | G22: 3 | H22: 0 | I22: 0 | J22: 3 | K22: N | L22: KHS1 | M22: KMBK | N22: 2611N | O22: THLCH | P22: LCH04 | Q22: IA | R22: 2026-10-04 | S22: JPKMJ | T22: KMJ01 | U22: JPKMJ | V22: 2026-10-26 | W22: JP | Y22: PUS05 | Z22: KRPUS | AA22: WHA GC LOGISTICS COMPANY LIMITED | AB22: PTT GLOBAL CHEMICAL PUBLIC COMPANY LIMITED | AC22: 48480 | AD22: 55080 | AE22: OK | AH22: CHK | AI22: OK | AM22: TBKK13 | AN22: Dharaporn | AO22: LDPE INNOPLUS LD2420H | AP22: Normal | AW22: 0 | AX22: N | AY22: OBL | AZ22: CY-RTN 24-26/09/26 (PR2610001539 ) *PLS CHECK OPEN GATE BEFORE RETURN CTNR* | BA22: SI DD.29/9/26 | BB22: P | BC22: 2026-09-08 | BD22: 2026-09-29 | BE22: Y | BF22: RESIN | BG22: Line | BH22: S22 | BK22: LCHY5 | BL22: 2026-09-24 | BN22: 3 | BY22: FULL | BZ22: 11 | CC22: LCH04 | CF22: 0 Teu | CG22: CY/CY | CH22: POL: THLCH [KMBK/2611N]; T/S(1st): KRPUS [SKNT/2642E]; POD: JPKMJ [/] | CI22: kotchakorn.w@wha-gc.com | CJ22: PTT GLOBAL CHEMICAL PUBLIC COMPANY | CK22: MARUBENI INNOVEXIS CORPORATION | CL22: MARUBENI INNOVEXIS CORPORATION | CM22: CLOSED | CN22: 202610011700 | CO22: 202610022359 | CQ22: S19-2309008 | CR22: TH02GR | CS22: WHA GC LOGISTICS COMPANY LIMITED | CT22: N | CW22: 2026-10-02 | CX22: 390110
A23: HASLS22260901864 | B23: R40Hx1 | C23: 1 | D23: 1 | F23: 0 | G23: 0 | H23: 0 | I23: 1 | J23: 2 | K23: N | L23: KHS1 | M23: KMBK | N23: 2611N | O23: THLCH | P23: LCH04 | Q23: IA | R23: 2026-10-04 | S23: KRPUS | T23: PUS05 | U23: KRPUS | V23: 2026-10-12 | W23: KR | AA23: CONNEXT LOG (THAILAND) CO.,LTD. | AB23: LAEMTHONG POULTRY CO., LTD. | AC23: 24640 | AD23: 28640 | AE23: OK | AF23: SR | AH23: CHK | AI23: OK | AM23: TBKK97 | AN23: Arunphat W. (Aiw) | AO23: FROZEN CHICKEN PRODUCTS | AP23: Normal | AS23: RF// MIN:-18.0 MAX:-18.0 [COVER:CLOSE] | AT23: 45REx1 | AW23: 0 | AX23: N | AY23: OBL | AZ23: Pickup : 2026-09-30, Return : 2026-10-01 (Temp -18.0 / Vent Close) CLS TIME 03/10/26 @12.00 (1ST DATE RTN 02/10/2026 W/O RENT,ELECTRIC) | BA23: FM SWAT 2610N 23/09ACTUAL SHIPPER : LAEMTHONG POULTRY CO., LTD. CY DATE : 30/09/2026 RTN DATE : 01/10/2026Comm : Frozen chicken products (HS code 0207141020)G.W. : 24640 kgsTemp : -18 CelsiusREQUEST NO DAIKIN , NEW CONTAINER GRADE A | BB23: P | BC23: 2026-09-21 | BD23: 2026-10-01 | BE23: Y | BF23: FROZEN CHICKEN PRODUCTS | BG23: Line | BH23: S22 | BK23: LCH27 | BL23: 2026-09-30 | BR23: 1 | BY23: FULL | CA23: Y | CC23: LCH04 | CF23: 0 Teu | CG23: CY/CY | CI23: export_cs@cnlthailand.com | CJ23: LAEMTHONG POULTRY CO., LTD. | CK23: TO THE ORDER OF | CL23: NEW ASIA CO.,LTD | CM23: CLOSED | CN23: 202610011700 | CO23: 202610022359 | CP23: 45RE x1: RF(Temp:-18.0' / Cover:CLOSE) | CQ23: S22-2403020 | CR23: THTS51 | CS23: CONNEXT LOG (THAILAND) CO.,LTD. | CT23: N | CW23: 2026-10-04
A24: HASLS22260901302 | B24: 40Hx2 | C24: 2 | D24: 2 | F24: 0 | G24: 0 | H24: 0 | I24: 2 | J24: 4 | K24: N | L24: KHS1 | M24: KMBK | N24: 2611N | O24: THLCH | P24: LCH04 | Q24: IA | R24: 2026-10-04 | S24: VNSGN | T24: SGN03 | U24: VNSGN | V24: 2026-10-06 | W24: IA | AA24: CANVAS GLOBAL LOGISTICS (THAILAND) CO., LTD. | AB24: SANJIANG CHEMICAL FIBER (THAILAND) CO.,LTD | AC24: 44817.8 | AD24: 52817.8 | AE24: OK | AH24: CHK | AI24: OK | AM24: TBKK97 | AN24: Arunphat W. (Aiw) | AO24: POLYESTER STAPLE FIBER | AP24: Normal | AW24: 0 | AX24: N | AZ24: Pickup : 2026-09-28, Return : 2026-09-29 (1ST RTN 29/09 W/O RENT) ** PLEASE CHECK OPEN GATE BEFORE RETURN CNTR ** | BB24: P | BC24: 2026-09-15 | BD24: 2026-09-30 | BE24: Y | BF24: POLYESTER STAPLE FIBER | BG24: Line | BH24: S22 | BK24: LCH27 | BL24: 2026-09-28 | BP24: 2 | BY24: FULL | CA24: Y | CC24: LCH04 | CF24: 0 Teu | CG24: CY/CY | CI24: cs.log@canvasglobal-log.co.th | CJ24: CANVAS GLOBAL LOGISTICS (THAILAND) | CK24: THAMI CORPORATION | CL24: THAMI CORPORATION | CN24: 202610011700 | CO24: 202610022359 | CQ24: S22-2609010 | CR24: THTWN1 | CS24: CANVAS GLOBAL LOGISTICS (THAILAND) CO., LTD. | CT24: N | CW24: 2026-10-03 | CX24: 550320
A25: HASLS22260900036 | B25: 40Hx1 | C25: 1 | D25: 1 | F25: 0 | G25: 0 | H25: 0 | I25: 1 | J25: 2 | K25: N | L25: KHS1 | M25: KMBK | N25: 2611N | O25: THLCH | P25: LCH04 | Q25: IA | R25: 2026-10-04 | S25: JPSBS | T25: SBS01 | U25: JPSBS | V25: 2026-10-18 | W25: JP | Y25: PUS05 | Z25: KRPUS | AA25: SCGJWD LOGISTICS PUBLIC COMPANY LIMITED | AB25: THAI POLYETHYLENE CO., LTD. | AC25: 25757.4 | AD25: 29757.4 | AE25: OK | AF25: SR | AH25: CHK | AI25: OK | AM25: TBKK19 | AN25: Kanokporn | AO25: POLYPROPYLENE RESIN | AP25: Normal | AW25: 0 | AX25: N | AY25: OBL | AZ25: CY-RTN 22-24/09/26 ( INV 3031061433 ) EXTEND CLS 25/09/26 @23.59 | BA25: ROLL OVER FROM PREVIOUS VSL SKOR 2611N BY ALLOATION TEAM MS.TARN APRPOVED COST IS UNDER HA DD.24/09 NOT SHOW CHARGE, SURRENDER B/L | BB25: P | BC25: 2026-09-01 | BD25: 2026-10-01 | BE25: Y | BF25: RESIN | BG25: Line | BH25: S22 | BK25: LCHY5 | BL25: 2026-09-22 | BP25: 1 | BY25: FULL | BZ25: 4 | CC25: LCH04 | CF25: 0 Teu | CG25: CY/CY | CH25: POL: THLCH [KMBK/2611N]; T/S(1st): KRPUS [SKNT/2641E]; POD: JPSBS [/] | CI25: natwalad@scgjwd.com | CJ25: THAI POLYETHYLENE CO.,LTD. | CK25: MITSUI & CO., LTD. | CL25: 1) MITSUI & CO., LTD. | CM25: CLOSED | CN25: 202610011700 | CO25: 202610022359 | CQ25: S19-2308040 | CR25: TH0235 | CS25: SCGJWD LOGISTICS PUBLIC COMPANY LIMITED | CT25: N | CW25: 2026-10-04 | CX25: 390210 | CY25: ROLL OVER FROM PREVIOUS VSL SKOR 2611N BY ALLOATION TEAM MS.TARN APRPOVED COST IS UNDER HA DD.24/09
A26: HASLS22260901909 | B26: 40Hx4 | C26: 4 | D26: 4 | F26: 0 | G26: 0 | H26: 0 | I26: 4 | J26: 8 | K26: N | L26: KHS1 | M26: KMBK | N26: 2611N | O26: THLCH | P26: LCH04 | Q26: IA | R26: 2026-10-04 | S26: VNSGN | T26: SGN03 | U26: VNSGN | V26: 2026-10-06 | W26: IA | AA26: CANVAS GLOBAL LOGISTICS (THAILAND) CO., LTD. | AB26: SANJIANG CHEMICAL FIBER (THAILAND) CO.,LTD | AC26: 97632.2 | AD26: 113632.2 | AE26: OK | AH26: CHK | AM26: TBKK97 | AN26: Arunphat W. (Aiw) | AO26: POLYESTER STAPLE FIBER | AP26: Normal | AW26: 0 | AX26: N | AZ26: Pickup : 2026-09-29, Return : 2026-09-30 | BB26: P | BC26: 2026-09-21 | BD26: 2026-10-02 | BE26: Y | BF26: POLYESTER STAPLE FIBER | BG26: Line | BH26: S22 | BK26: LCHY5 | BL26: 2026-09-29 | BP26: 4 | BY26: FULL | CA26: Y | CC26: LCH04 | CF26: 0 Teu | CG26: CY/CY | CI26: cs.log@canvasglobal-log.co.th | CJ26: SANJIANG CHEMICAL FIBER (THAILAND) | CK26: CONG TY TNHH CONG NGHE JING TAI | CL26: CONG TY TNHH CONG NGHE JING TAI | CN26: 202610011700 | CO26: 202610022359 | CQ26: S22-2609010 | CR26: THTWN1 | CS26: CANVAS GLOBAL LOGISTICS (THAILAND) CO., LTD. | CT26: N | CW26: 2026-10-04 | CX26: 550320
A27: HASLS22260902168 | B27: 40Hx1 | C27: 1 | D27: 1 | F27: 0 | G27: 0 | H27: 0 | I27: 1 | J27: 2 | K27: N | L27: KHS1 | M27: KMBK | N27: 2611N | O27: THLCH | P27: LCH04 | Q27: IA | R27: 2026-10-04 | S27: KRPUS | T27: PUS05 | U27: KRPUS | V27: 2026-10-12 | W27: KR | AA27: H & FRIENDS GTL (THAILAND) CO., LTD. | AB27: AUTOLIV (THAILAND) LIMITED | AC27: 4434.81 | AD27: 8434.81 | AE27: OK | AF27: SR | AH27: CON | AI27: OK | AM27: TBKK47 | AN27: Tarn(Supaporn) | AO27: CUSHION THORAX SIDE AIRBAG | AP27: Normal | AW27: 0 | AX27: N | AY27: OBL | AZ27: Pickup : 2026-10-01, Return : 2026-10-01 | BA27: FM 1X40 HC DD 28/09 FM LCHY5 REQUEST CONTAINER CLEAN & NO SMEL | BB27: P | BC27: 2026-09-23 | BD27: 2026-10-01 | BE27: Y | BF27: SEAT BELT | BG27: Line | BH27: S22 | BK27: LCH28 | BL27: 2026-10-01 | BP27: 1 | BY27: FULL | CA27: Y | CC27: LCH04 | CF27: 0 Teu | CG27: CY/CY | CI27: bkksea@hnfriends.com | CJ27: H & FRIENDS GTL (THAILAND) CO., LTD | CK27: KWAY LOGIS CO.,LTD. | CL27: KWAY LOGIS CO.,LTD. | CM27: CLOSED | CN27: 202610011700 | CO27: 202610022359 | CQ27: S19-1911051 | CR27: THTIK5 | CS27: H & FRIENDS GTL (THAILAND) CO., LTD. | CT27: N | CW27: 2026-10-04
A28: HASLS22260802304 | B28: 40Hx1 | C28: 1 | D28: 1 | F28: 0 | G28: 0 | H28: 0 | I28: 1 | J28: 2 | K28: N | L28: KHS1 | M28: KMBK | N28: 2611N | O28: THLCH | P28: LCH04 | Q28: IA | R28: 2026-10-04 | S28: JPKIJ | T28: KIJ01 | U28: JPKIJ | V28: 2026-10-21 | W28: JP | Y28: PUS05 | Z28: KRPUS | AA28: WHA GC LOGISTICS COMPANY LIMITED | AB28: PTT GLOBAL CHEMICAL PUBLIC COMPANY LIMITED | AC28: 24240 | AD28: 28240 | AE28: OK | AH28: CHK | AI28: OK | AM28: TBKK13 | AN28: Dharaporn | AO28: HIGH DENSITY POLYETHYLENE | AP28: Normal | AW28: 0 | AX28: N | AY28: OBL | AZ28: CY-RTN 25-28/09/26 (PR2610001758 ) *PLS CHECK OPEN GATE BEFORE RETURN CTNR* | BA28: SI DD.22/9/26 FM LCH28 FM SWIC 2610N DD.08/09/26 | BB28: P | BC28: 2026-08-27 | BD28: 2026-09-23 | BE28: Y | BF28: RESIN | BG28: Line | BH28: S22 | BK28: LCHY5 | BL28: 2026-09-25 | BP28: 1 | BY28: FULL | BZ28: 6 | CC28: LCH04 | CF28: 0 Teu | CG28: CY/CY | CH28: POL: THLCH [KMBK/2611N]; T/S(1st): KRPUS [OSVY/2655E]; POD: JPKIJ [/] | CI28: kotchakorn.w@wha-gc.com | CJ28: PTT GLOBAL CHEMICAL PUBLIC COMPANY | CK28: TOYOTSU CHEMIPLAS CORPORATION | CL28: TOYOTSU CHEMIPLAS CORPORATION | CM28: CLOSED | CN28: 202610011700 | CO28: 202610022359 | CQ28: S19-2309008 | CR28: TH02GR | CS28: WHA GC LOGISTICS COMPANY LIMITED | CT28: N | CW28: 2026-10-02 | CX28: 390120
A29: HASLS22260902505 | B29: 40Hx1 | C29: 1 | D29: 1 | F29: 0 | G29: 0 | H29: 0 | I29: 1 | J29: 2 | K29: N | L29: KHS1 | M29: KMBK | N29: 2611N | O29: THLCH | P29: LCH04 | Q29: IA | R29: 2026-10-04 | S29: RUVVO | T29: VVO01 | U29: RUVVO | V29: 2026-10-19 | W29: RU | Y29: PUS05 | Z29: KRPUS | AA29: SRITHAI TOYO LOGISTICS CO., LTD. | AB29: YOKOHAMA TIRE MANUFACTURING (THAILAND) CO., LTD. | AC29: 10147.387 | AD29: 14147.387 | AE29: OK | AH29: CHK | AI29: OK | AM29: TH0011 | AN29: Nannaapust Sukporntaweewat | AO29: NEW "YOKOHAMA" BRAND TIRES | AP29: Normal | AW29: 0 | AX29: N | AY29: OBL | AZ29: [FIX][FIX]CY-RTN : 28-30/09/2026 *1ST RETURN CNTR DD.30/09/2026* RQST CNTR GRADE A REF : WK40 | BB29: P | BC29: 2026-09-28 | BD29: 2026-09-30 | BE29: Y | BF29: NEW TIRE | BG29: Line | BH29: S22 | BK29: LCHY5 | BL29: 2026-09-28 | BP29: 1 | BY29: FULL | BZ29: 5 | CC29: LCH04 | CF29: 0 Teu | CG29: CY/CY | CH29: POL: THLCH [KMBK/2611N]; T/S(1st): KRPUS [SDTR/2629N]; POD: RUVVO [/] | CI29: sty-cs01@srithaigroup.com | CJ29: YOKOHAMA TIRE MANUFACTURING | CK29: YOKOHAMA RUSSIA LLC | CL29: YOKOHAMA RUSSIA LLC | CM29: CLOSED | CN29: 202610011700 | CO29: 202610022359 | CQ29: S22-2412044 | CR29: TH002V | CS29: SRITHAI TOYO LOGISTICS CO., LTD. | CT29: N | CW29: 2026-10-04 | CX29: 401110
A30: HASLS22260901548 | B30: 40Hx1 | C30: 1 | D30: 1 | F30: 0 | G30: 0 | H30: 0 | I30: 1 | J30: 2 | K30: N | L30: KHS1 | M30: KMBK | N30: 2611N | O30: THLCH | P30: LCH04 | Q30: IA | R30: 2026-10-04 | S30: KRKAN | T30: KAN06 | U30: KRKAN | V30: 2026-10-14 | W30: KR | AA30: EASTERN AIR LOGISTICS CO., LTD. | AB30: Y-MECO CO., LTD. | AC30: 8078 | AD30: 12078 | AE30: OK | AF30: SR | AH30: CON | AM30: TBKK47 | AN30: Tarn(Supaporn) | AO30: ASSY COND | AP30: Normal | AW30: 0 | AX30: N | AZ30: Pickup : 2026-10-01, Return : 2026-10-01 ** PLEASE CHECK OPEN GATE BEFORE RETURN CNTR ** | BA30: FM LCHY5 | BB30: P | BC30: 2026-09-17 | BD30: 2026-10-01 | BE30: Y | BF30: ASSY COND | BG30: Line | BH30: S22 | BK30: LCH28 | BL30: 2026-10-01 | BP30: 1 | BY30: FULL | CA30: Y | CC30: LCH04 | CF30: 0 Teu | CG30: CY/CY | CI30: seahq_export4@easternair.co.th;seahq_export2@easternair.co.th;seahq_export@easternair.co.th | CJ30: EASTERN AIR LOGISTICS CO.,LTD | CK30: ISAC CO.,LTD | CL30: ISAC CO.,LTD | CN30: 202610011700 | CO30: 202610022359 | CQ30: S22-2209015 | CR30: THTL32 | CS30: EASTERN AIR LOGISTICS CO., LTD. | CT30: N | CW30: 2026-10-04 | CX30: 841590
A31: HASLS22260900250 | B31: 40Hx1 | C31: 1 | D31: 1 | F31: 0 | G31: 0 | H31: 0 | I31: 1 | J31: 2 | K31: N | L31: KHS1 | M31: KMBK | N31: 2611N | O31: THLCH | P31: LCH04 | Q31: IA | R31: 2026-10-04 | S31: JPHSM | T31: HSM01 | U31: JPHSM | V31: 2026-10-23 | W31: JP | Y31: PUS05 | Z31: KRPUS | AA31: WHA GC LOGISTICS COMPANY LIMITED | AB31: PTT GLOBAL CHEMICAL PUBLIC COMPANY LIMITED | AC31: 24997.5 | AD31: 28997.5 | AE31: OK | AH31: CHK | AI31: OK | AM31: TBKK13 | AN31: Dharaporn | AO31: LOW DENSITY POLYETHYLENE | AP31: Normal | AW31: 0 | AX31: N | AY31: OBL | AZ31: CY-RTN 22-27/09/26 *PLS CHECK OPEN GATE BEFORE RETURN CTNR* | BA31: SI DD.25/9/26 FM SWAT 2610N 10/09 | BB31: P | BC31: 2026-09-03 | BD31: 2026-09-25 | BE31: Y | BF31: RESIN | BG31: Line | BH31: S22 | BK31: LCH27 | BL31: 2026-09-22 | BP31: 1 | BY31: FULL | BZ31: 7 | CC31: LCH04 | CF31: 0 Teu | CG31: CY/CY | CH31: POL: THLCH [KMBK/2611N]; T/S(1st): KRPUS [HSWH/2659E]; POD: JPHSM [/] | CI31: jariya.c@wha-gc.com | CJ31: PTT GLOBAL CHEMICAL PUBLIC COMPANY | CK31: MARUBENI INNOVEXIS CORPORATION | CL31: MARUBENI INNOVEXIS CORPORATION | CM31: CLOSED | CN31: 202610011700 | CO31: 202610022359 | CQ31: S19-2309008 | CR31: TH02GR | CS31: WHA GC LOGISTICS COMPANY LIMITED | CT31: N | CW31: 2026-10-03 | CX31: 390140
A32: HASLS22260901880 | B32: 40Hx1 | C32: 1 | D32: 1 | F32: 0 | G32: 0 | H32: 0 | I32: 1 | J32: 2 | K32: N | L32: KHS1 | M32: KMBK | N32: 2611N | O32: THLCH | P32: LCH04 | Q32: IA | R32: 2026-10-04 | S32: VNSGN | T32: SGN03 | U32: VNSGN | V32: 2026-10-06 | W32: IA | AA32: BEE LOGISTICS (THAILAND) CO., LTD. | AB32: SIRI LABORATORIES CO., LTD. | AC32: 25050 | AD32: 29050 | AE32: OK | AF32: SR | AH32: CHK | AM32: TBKK28 | AN32: Nustsireerach | AO32: LAUNDRY DETERGENT | AP32: Normal | AW32: 0 | AX32: N | AZ32: Pickup : 2026-09-30, Return : 2026-10-01 | BA32: 2660 | BB32: P | BC32: 2026-09-21 | BD32: 2026-10-02 | BE32: Y | BF32: LAUNDRY DETERGENT | BG32: Line | BH32: S22 | BK32: LCHY5 | BL32: 2026-09-30 | BP32: 1 | BY32: FULL | CA32: Y | CC32: LCH04 | CF32: 0 Teu | CG32: CY/CY | CI32: exp4.th@beelogistics.com | CJ32: BEE LOGISTICS (THAILAND) CO., LTD. | CK32: BOND GLOBAL LOGISTICS JOINT STOCK | CL32: BOND GLOBAL LOGISTICS JOINT STOCK | CN32: 202610011700 | CO32: 202610022359 | CQ32: S22-2308015 | CR32: THTIK1 | CS32: BEE LOGISTICS (THAILAND) CO., LTD. | CT32: N | CW32: 2026-10-03 | CX32: 340250
A33: HASLS22260801555 | B33: 40Hx3 | C33: 3 | D33: 3 | F33: 0 | G33: 0 | H33: 0 | I33: 3 | J33: 6 | K33: N | L33: KHS1 | M33: KMBK | N33: 2611N | O33: THLCH | P33: LCH04 | Q33: IA | R33: 2026-10-04 | S33: JPSDJ | T33: SDJ01 | U33: JPSDJ | V33: 2026-10-25 | W33: JP | Y33: PUS05 | Z33: KRPUS | AA33: OSC SIAM SILICA CO., LTD. | AB33: OSC SIAM SILICA CO., LTD. | AC33: 45780 | AD33: 57780 | AE33: OK | AH33: CHK | AI33: OK | AM33: JOSA03 | AN33: Hongjuan Li (Ms.) | AO33: SILICON DIOXIDE | AP33: T/S | AW33: 0 | AX33: N | AY33: OBL | AZ33: Pickup : 2026-09-28, Return : 2026-09-28 (1ST RETURN 30/09/26) | BA33: FM SWAT 2610N 15/09 FM LCHY5 | BB33: C | BC33: 2026-08-19 | BD33: 2026-09-30 | BE33: Y | BF33: SILICON DIOXIDE | BG33: Line | BH33: S22 | BK33: LCH28 | BL33: 2026-09-28 | BP33: 3 | BY33: FULL | BZ33: 7 | CA33: Y | CC33: LCH04 | CF33: 0 Teu | CG33: CY/CY | CH33: POL: THLCH [KMBK/2611N]; T/S(1st): KRPUS [TYTR/2638E]; POD: JPSDJ [/] | CI33: vratchanee@apsilica.com | CJ33: OSC SIAM SILICA CO., LTD. | CK33: TOYO TIRE CORPORATION | CL33: TOYO TIRE CORPORATION | CM33: CLOSED | CN33: 202610011700 | CO33: 202610022359 | CQ33: J02-2003008 | CR33: THTQ3B | CS33: OSC SIAM SILICA CO., LTD. | CT33: N | CW33: 2026-10-03 | CX33: 281122
A34: HASLS22260901355 | B34: 40Hx1 | C34: 1 | D34: 1 | F34: 0 | G34: 0 | H34: 0 | I34: 1 | J34: 2 | K34: N | L34: KHS1 | M34: KMBK | N34: 2611N | O34: THLCH | P34: LCH04 | Q34: IA | R34: 2026-10-04 | S34: VNSGN | T34: SGN03 | U34: VNSGN | V34: 2026-10-06 | W34: IA | AA34: ACCORD PILOT LOGISTICS (THAILAND) CO., LTD. | AB34: HMC POLYMERS CO., LTD. | AC34: 24624 | AD34: 28624 | AE34: OK | AH34: CHK | AI34: OK | AM34: TBKK19 | AN34: Kanokporn | AO34: POLYPROPYLENE | AP34: Normal | AW34: 0 | AX34: N | AZ34: Pickup : 2026-09-28, Return : 2026-09-29 (1ST RTN DD: 30/09/26 WO/RENT) | BA34: FM SWSP 2609N 23/09 FM LCH27REQ FREE TIME DEM 21 DAYS // DET 14 DAYS AT DESTINATION | BB34: P | BC34: 2026-09-16 | BD34: 2026-10-01 | BE34: Y | BF34: POLYPROPYLENE | BG34: Line | BH34: S22 | BK34: LCH28 | BL34: 2026-09-28 | BP34: 1 | BY34: FULL | CA34: Y | CC34: LCH04 | CF34: 0 Teu | CG34: CY/CY | CI34: chayanit@pilot.co.th | CJ34: HMC POLYMERS CO., LTD. | CK34: VI LU CO LTD. | CL34: VI LU CO LTD. | CN34: 202610011700 | CO34: 202610022359 | CQ34: S19-2308037 | CR34: THTIPI | CS34: ACCORD PILOT LOGISTICS (THAILAND) CO., LTD. | CT34: N | CW34: 2026-10-04 | CX34: 390210
A35: HASLS22260901795 | B35: 40Hx1 | C35: 1 | D35: 1 | F35: 0 | G35: 0 | H35: 0 | I35: 1 | J35: 2 | K35: N | L35: KHS1 | M35: KMBK | N35: 2611N | O35: THLCH | P35: LCH04 | Q35: IA | R35: 2026-10-04 | S35: VNSGN | T35: SGN03 | U35: VNSGN | V35: 2026-10-06 | W35: IA | AA35: EAST-LINK CORPORATION CO., LTD. | AB35: TRI-WALL PACKAGING (THAI) LTD. | AC35: 8071.41 | AD35: 12071.41 | AE35: OK | AF35: SR | AH35: CON | AI35: OK | AM35: TBKK13 | AN35: Dharaporn | AO35: CORRUGATED PAPER BOARD | AP35: Normal | AW35: 0 | AX35: N | AZ35: Pickup : 2026-09-30, Return : 2026-10-01 ** PLEASE CHECK OPEN GATE BEFORE RETURN CNTR ** | BA35: FM LCHY5RQS CLEAN & GOOD CONTAINER CONDITION. | BB35: C | BC35: 2026-09-21 | BD35: 2026-09-30 | BE35: Y | BF35: CORRUGATED PAPER BOARD | BG35: Line | BH35: S22 | BK35: LCH28 | BL35: 2026-09-30 | BP35: 1 | BY35: FULL | CA35: Y | CC35: LCH04 | CF35: 0 Teu | CG35: CY/CY | CI35: rockwell@eastlink-group.com | CJ35: EAST-LINK CORPORATION CO., LTD. | CK35: DOLPHIN SEA AIR SERVICES | CL35: DOLPHIN SEA AIR SERVICES | CN35: 202610011700 | CO35: 202610022359 | CQ35: S22-2308019 | CR35: TH03OT | CS35: EAST-LINK CORPORATION CO., LTD. | CT35: N | CW35: 2026-10-03 | CX35: 480810
A36: HASLS22260901797 | B36: 20'x1 40Hx1 | C36: 2 | D36: 2 | F36: 0 | G36: 1 | H36: 0 | I36: 1 | J36: 3 | K36: N | L36: KHS1 | M36: KMBK | N36: 2611N | O36: THLCH | P36: LCH04 | Q36: IA | R36: 2026-10-04 | S36: VNSGN | T36: SGN03 | U36: VNSGN | V36: 2026-10-06 | W36: IA | AA36: KORCHINA FREIGHT (THAILAND) CO., LTD. | AB36: YOKOHAMA TIRE MANUFACTURING (THAILAND) CO., LTD. | AC36: 16134.48 | AD36: 22334.48 | AE36: OK | AF36: SR | AH36: CHK | AI36: OK | AM36: A1029 | AN36: LEE HWA DONG | AO36: STEEL SPOOLS ,PLASTIC PALLETS | AP36: Normal | AW36: 0 | AX36: N | AZ36: Pickup : 2026-09-29, Return : 2026-09-29 (1ST RTN DD: 30/09/26 WO/RENT) **CHECK OPENGATE BEFORE RETURN CNTR** | BA36: FM 1X40HQ 23/09 | BB36: C | BC36: 2026-09-21 | BD36: 2026-09-30 | BE36: Y | BF36: STEEL SPOOLS ,PLASTIC PALLETS | BG36: Line | BH36: S22 | BK36: LCHY5 | BL36: 2026-09-29 | BN36: 1 | BP36: 1 | BY36: FULL | CA36: Y | CC36: LCH04 | CF36: 0 Teu | CG36: CY/CY | CI36: seaexport4@korchina.co.th;seaexport2@korchina.co.th;seaexport@korchina.co.th;seaexport3@korchina.co.th | CJ36: KORCHINA FREIGHT (THAILAND)CO.,LTD. | CK36: HS HYOSUNG GLOBAL LOGISTICS VINA | CL36: HS HYOSUNG GLOBAL LOGISTICS VINA | CN36: 202610011700 | CO36: 202610022359 | CQ36: A1XZT-22018 | CR36: THTKT0 | CS36: KORCHINA FREIGHT (THAILAND) CO., LTD. | CT36: N | CW36: 2026-10-04 | CX36: 732690
A37: HASLS22260902009 | B37: 40Hx1 | C37: 1 | D37: 1 | F37: 0 | G37: 0 | H37: 0 | I37: 1 | J37: 2 | K37: N | L37: KHS1 | M37: KMBK | N37: 2611N | O37: THLCH | P37: LCH04 | Q37: IA | R37: 2026-10-04 | S37: KRPUS | T37: PUS05 | U37: KRPUS | V37: 2026-10-12 | W37: KR | AA37: H & FRIENDS GTL (THAILAND) CO., LTD. | AB37: AUTOLIV (THAILAND) LIMITED | AC37: 9602.33 | AD37: 13602.33 | AE37: OK | AF37: SR | AH37: CON | AI37: OK | AM37: TBKK47 | AN37: Tarn(Supaporn) | AO37: CUSHION PASSENGER AIRBAG | AP37: Normal | AW37: 0 | AX37: N | AY37: OBL | AZ37: Pickup : 2026-09-30, Return : 2026-09-30 | BA37: FM LCHY5REQUEST CONTAINER CLEAN & NO SMEL | BB37: P | BC37: 2026-09-22 | BD37: 2026-10-01 | BE37: Y | BF37: SEAT BELT | BG37: Line | BH37: S22 | BK37: LCH28 | BL37: 2026-09-30 | BP37: 1 | BY37: FULL | CA37: Y | CC37: LCH04 | CF37: 0 Teu | CG37: CY/CY | CI37: bkksea@hnfriends.com | CJ37: H & FRIENDS GTL (THAILAND) CO.,LTD. | CK37: KWAY LOGIS CO.,LTD. | CL37: KWAY LOGIS CO.,LTD. | CM37: CLOSED | CN37: 202610011700 | CO37: 202610022359 | CQ37: S19-1911051 | CR37: THTIK5 | CS37: H & FRIENDS GTL (THAILAND) CO., LTD. | CT37: N | CW37: 2026-10-04
A38: HASLS22260901894 | B38: 20'x1 | C38: 1 | D38: 1 | F38: 0 | G38: 1 | H38: 0 | I38: 0 | J38: 1 | K38: N | L38: KHS1 | M38: KMBK | N38: 2611N | O38: THLCH | P38: LCH04 | Q38: IA | R38: 2026-10-04 | S38: VNSGN | T38: SGN03 | U38: VNIPH | V38: 2026-10-06 | W38: IA | X38: Truck | AA38: BDP ASIA-PACIFIC LTD. | AB38: PPG COATINGS (THAILAND) CO., LTD. | AC38: 1978 | AD38: 4178 | AE38: OK | AF38: SR | AH38: CHK | AI38: OK | AM38: TBKK28 | AN38: Nustsireerach | AO38: LACQUER | AP38: Normal | AQ38: DG(Mix)22GPx1 (CLS 3 / UN 1263) | AR38: 22GPx1 | AW38: 0 | AX38: N | AZ38: **APPROVED BY JEONG-YONG UM DD.22/09/26 ** MIX DG22GPx1 (CLS 3 / UN 1263) Pickup : 2026-10-01, Return @JWD : 2026-10-02 | BB38: P | BC38: 2026-09-21 | BD38: 2026-09-30 | BE38: Y | BF38: LACQUER | BG38: Line | BH38: S22 | BK38: LCHY5 | BL38: 2026-10-01 | BN38: 1 | BY38: FULL | CA38: Y | CC38: LCH04 | CF38: 3 Class x 1 Teu (Approval), | CG38: CY/CY | CI38: wanruedee.s@psabdp.com | CJ38: PPG COATINGS (THAILAND) CO., LTD. | CK38: DONA NEW TOWER NATURAL DRINK AND | CL38: DONA NEW TOWER NATURAL DRINK AND | CN38: 202610011700 | CO38: 202610022359 | CP38: 22GP x1: DG(UNNo.:1263/ Class:3) | CQ38: S19-2308003 | CR38: BB2252 | CS38: BDP ASIA-PACIFIC LTD. | CT38: N | CW38: 2026-10-03 | CX38: 320810
A39: HASLS22260900446 | B39: 20'x3 | C39: 3 | D39: 3 | F39: 0 | G39: 3 | H39: 0 | I39: 0 | J39: 3 | K39: N | L39: KHS1 | M39: KMBK | N39: 2611N | O39: THLCH | P39: LCH04 | Q39: IA | R39: 2026-10-04 | S39: KRPUS | T39: PUS05 | U39: KRPUS | V39: 2026-10-12 | W39: KR | AA39: IMEX PRO LOGISTICS CO., LTD. | AB39: AEKKACHAI CHOMCHOEI | AC39: 66000 | AD39: 72600 | AE39: OK | AF39: SR | AH39: CON | AI39: OK | AM39: TH0031 | AN39: Pattarapong Saengthong | AO39: STAINLESS STEEL SLUDGE | AP39: Normal | AW39: 0 | AX39: N | AY39: OBL | AZ39: Pickup : 2026-09-19, Return : 2026-09-21 **PLS CHECK OPENGATE BEFORE RETURN CNTR** | BA39: ROLL OVER FORM PREVIOUS VSL SWMM 2609N BY ALLOCATION TEAM MS.TARN APRPOVED COST IS UNDER HA DD.24/09 FM HAB 2611N DUE TO SKIP BUSAN 09/09SHIPPER : AEKKACHAI CHOMCHOEI TAX ID : 3451100628488 | BB39: P | BC39: 2026-09-04 | BD39: 2026-09-29 | BE39: Y | BF39: CUTS STAINLESS STEEL | BG39: Line | BH39: S22 | BK39: LCH27 | BL39: 2026-09-19 | BN39: 3 | BY39: FULL | CA39: Y | CC39: LCH04 | CF39: 0 Teu | CG39: CY/CY | CI39: sunisa.c@imexproth.com | CJ39: IMEX PRO LOGISTICS CO., LTD. | CK39: FORMAN SHIPPING CO. LTD. | CL39: FORMAN SHIPPING CO. LTD. | CM39: CLOSED | CN39: 202610011700 | CO39: 202610022359 | CQ39: S22-2601027 | CR39: THTV8G | CS39: IMEX PRO LOGISTICS CO., LTD. | CT39: N | CW39: 2026-10-04 | CY39: ROLL OVER FORM PREVIOUS VSL SWMM 2609N BY ALLOCATION TEAM MS.TARN APRPOVED COST IS UNDER HA DD.24/09
A40: HASLS22260900040 | B40: 20'x3 | C40: 3 | D40: 3 | F40: 0 | G40: 3 | H40: 0 | I40: 0 | J40: 3 | K40: N | L40: KHS1 | M40: KMBK | N40: 2611N | O40: THLCH | P40: LCH04 | Q40: IA | R40: 2026-10-04 | S40: VNSGN | T40: SGN03 | U40: VNSGN | V40: 2026-10-06 | W40: IA | AA40: UNITED MARINE LOGISTIC CO., LTD. | AB40: WELLGROW GLASS INDUSTRY CO., LTD. | AC40: 43660 | AD40: 50260 | AE40: OK | AH40: CHK | AI40: OK | AM40: TH0011 | AN40: Nannaapust Sukporntaweewat | AO40: GLASS BOTTLE | AP40: Normal | AW40: 0 | AX40: N | AZ40: Pickup : 2026-09-28, Return : 2026-09-29 | BA40: FM 4X20'GP DD.30/09/26 ADD COST CANCEL SPACE THB2,000 | BB40: P | BC40: 2026-09-01 | BD40: 2026-10-01 | BE40: Y | BF40: GLASS BOTTLE | BG40: Line | BH40: S22 | BK40: LCH27 | BL40: 2026-09-28 | BN40: 3 | BY40: FULL | CA40: Y | CC40: LCH04 | CF40: 0 Teu | CG40: CY/CY | CI40: natwlan@umac.co.th | CJ40: WELLGROW GLASS INDUSTRY CO., LTD. | CK40: MARICO SOUTH EAST ASIA CORPORATION | CL40: MARICO SOUTH EAST ASIA CORPORATION | CN40: 202610011700 | CO40: 202610022359 | CQ40: S22-2406015 | CR40: BB1277 | CS40: UNITED MARINE LOGISTIC CO., LTD. | CT40: N | CW40: 2026-10-01 | CX40: 701090
...

Sheet 3.GateMove
A1: Container No | B1: Location | C1: Move | D1: GateDate | E1: GateTime | F1: BL No | G1: Shipper | H1: TPSZ | I1: Remark | J1: EmpName | K1: CND | L1: F/E | M1: BK No | N1: BK QTY | O1: Built Year | P1: RF Brand | Q1: RF Model | R1: Vessel | S1: Voyage | T1: LWHARF | U1: POL | V1: POL Date | W1: POD | X1: POD Date | Y1: SOC | Z1: Seal No | AA1: Truck No | AB1: Haulier | AC1: Driver Tel | AD1: InpDate | AE1: InpTime | AF1: EmpNo | AG1: SendId | AH1: SendDate | AI1: Cnee Code | AJ1: Cnee Name | AK1: Weight
A2: DFSU7561434 | B2: LCH04 | C2: IFV | D2: 2026-09-29 | E2: 2244 | F2: HASLS22260900886 | G2: ROHLIG (THAILAND) LIMITED | H2: 45GP | I2: EMAIL | J2: EDI2 | L2: Full | M2: HASLS22260900886 | N2: 40Hx1 | O2: 2014 | R2: KMBK | S2: 2611N | T2: LCH04 | U2: THLCH | V2: 2026-10-04 | W2: RUVVO | X2: 2026-10-12 | AD2: 2026-09-30 | AE2: 0200 | AF2: EDI2 | AJ2: RECKITT BENCKISER HEALTHCARE LLC
A3: FBIU5090221 | B3: LCH04 | C3: IFV | D3: 2026-10-01 | E3: 1105 | F3: HASLS22260902143 | G3: MAXCORE LOGISTICS CO., LTD. | H3: 45RE | I3: EMAIL | J3: EDI2 | L3: Full | M3: HASLS22260902143 | N3: R40Hx1 | O3: 2021 | P3: CARRIER | Q3: 69NT40-561-503 | R3: KMBK | S3: 2611N | T3: LCH04 | U3: THLCH | V3: 2026-10-04 | W3: KRPUS | X3: 2026-10-12 | AD3: 2026-10-01 | AE3: 1400 | AF3: EDI2 | AJ3: TO THE ORDER OF INDUSTRIAL BANK OF
A4: FBIU5092585 | B4: LCH04 | C4: IFV | D4: 2026-10-01 | E4: 2046 | F4: HASLS22260901848 | G4: GFPT PUBLIC COMPANY LIMITED. | H4: 45RE | I4: EMAIL | J4: EDI2 | L4: Full | M4: HASLS22260901848 | N4: R40Hx1 | O4: 2021 | P4: CARRIER | Q4: Primeline | R4: KMBK | S4: 2611N | T4: LCH04 | U4: THLCH | V4: 2026-10-04 | W4: KRPUS | X4: 2026-10-12 | AD4: 2026-10-02 | AE4: 0000 | AF4: EDI2 | AJ4: TO THE ORDER OF WOORI BANK SEOUL
A5: FBIU5102214 | B5: LCH04 | C5: IFV | D5: 2026-10-02 | E5: 1036 | F5: HASLS22260901768 | G5: GOLDEN SEA FROZEN FOODS CO.,LTD | H5: 45RE | I5: EMAIL | J5: EDI2 | L5: Full | M5: HASLS22260901768 | N5: R40Hx1 | O5: 2021 | P5: CARRIER | Q5: 69NT40-561-503 | R5: KMBK | S5: 2611N | T5: LCH04 | U5: THLCH | V5: 2026-10-04 | W5: VNSGN | X5: 2026-10-06 | AD5: 2026-10-02 | AE5: 1400 | AF5: EDI2 | AI5: VAVWZC | AJ5: KHANH LAN SEAFOOD IMPORT & EXPORT
A6: FBIU5371492 | B6: LCH04 | C6: IFV | D6: 2026-09-29 | E6: 0102 | F6: HASLS22260901282 | G6: KODAI (THAILAND) CO., LTD. | H6: 45RE | I6: EMAIL | J6: EDI2 | L6: Full | M6: HASLS22260901282 | N6: R40Hx1 | O6: 2023 | P6: CARRIER | Q6: 69NT40-571-112 | R6: KMBK | S6: 2611N | T6: LCH04 | U6: THLCH | V6: 2026-10-04 | W6: JPSDJ | X6: 2026-10-12 | AD6: 2026-09-29 | AE6: 0400 | AF6: EDI2 | AJ6: KODAI COMPANY LTD.
A7: FBIU5373392 | B7: LCH04 | C7: IFV | D7: 2026-09-29 | E7: 0707 | F7: HASLS22260901278 | G7: KODAI (THAILAND) CO., LTD. | H7: 45RE | I7: EMAIL | J7: EDI2 | L7: Full | M7: HASLS22260901278 | N7: R40Hx1 | O7: 2023 | P7: CARRIER | Q7: 69NT40-571-112 | R7: KMBK | S7: 2611N | T7: LCH04 | U7: THLCH | V7: 2026-10-04 | W7: JPISS | X7: 2026-10-12 | AD7: 2026-09-29 | AE7: 1000 | AF7: EDI2 | AJ7: KODAI COMPANY LTD.
A8: FSCU5835676 | B8: LCH04 | C8: IFV | D8: 2026-10-01 | E8: 1801 | F8: HASLS22260901847 | G8: GFPT PUBLIC COMPANY LIMITED. | H8: 45RE | I8: EMAIL | J8: EDI2 | L8: Full | M8: HASLS22260901847 | N8: R40Hx1 | O8: 2020 | P8: CARRIER | Q8: 69NT40-561-500 | R8: KMBK | S8: 2611N | T8: LCH04 | U8: THLCH | V8: 2026-10-04 | W8: KRPUS | X8: 2026-10-12 | AD8: 2026-10-01 | AE8: 2200 | AF8: EDI2 | AJ8: TO THE ORDER OF WOORI BANK SEOUL
A9: FSCU5894339 | B9: LCH04 | C9: IFV | D9: 2026-10-03 | E9: 1019 | F9: HASLS22260902145 | G9: MAXCORE LOGISTICS CO., LTD. | H9: 45RE | I9: EMAIL | J9: EDI2 | L9: Full | M9: HASLS22260902145 | N9: R40Hx1 | O9: 2020 | P9: CARRIER | Q9: 69NT40-561-500 | R9: KMBK | S9: 2611N | T9: LCH04 | U9: THLCH | V9: 2026-10-04 | W9: KRPUS | X9: 2026-10-12 | AD9: 2026-10-03 | AE9: 1400 | AF9: EDI2 | AJ9: TO THE ORDER OF INDUSTRIAL BANK OF
A10: FSCU5896429 | B10: LCH04 | C10: IFV | D10: 2026-10-01 | E10: 1829 | F10: HASLS22260902458 | G10: VENTE TRADE CO.,LTD. | H10: 45RE | I10: EMAIL | J10: EDI2 | L10: Full | M10: HASLS22260902458 | N10: R40Hx2 | O10: 2020 | P10: CARRIER | Q10: 69NT40-561-500 | R10: KMBK | S10: 2611N | T10: LCH04 | U10: THLCH | V10: 2026-10-04 | W10: RUVVO | X10: 2026-10-12 | AD10: 2026-10-01 | AE10: 2200 | AF10: EDI2 | AJ10: JOINT-STOCK COMPANY "GRAND-TRADE"
