Workbook

Sheet 1.Loading
A1: Container No. | B1: EQ Date | C1: Vessel | D1: Voyage | E1: Type Size | F1: CD | G1: R.C.V | H1: P.O.L | I1: P.O.D | J1: D.L.V | K1: F/E | L1: LEASE_TYPE | M1: Move Code | N1: Location | O1: Area | P1: Nation | Q1: Booking No. | R1: T/S | S1: S.O.C | T1: Service | U1: Remark | V1: Auth. No. | W1: Shipper | X1: PreVSLMove | Y1: Consignee | Z1: Notify | AA1: CNTR WGT. | AB1: L-Wharf(B/L) | AC1: D-Wharf(B/L)
A2: SKRU1900119 | B2: 2026-10-08 | C2: SWDN | D2: 2610N | E2: 22RE | F2: SD | G2: THLKR | H2: THLCH | I2: HKHKG | J2: HKHKG | K2: F | L2: ONE | M2: VFL | N2: LCH05 | O2: LCH | P2: TH | Q2: HASLS22260900990 | R2: N | S2: N | T2: CHT | V2: K0120024 | W2: THAI SUMMIT MARKETING CO., LTD. | X2: VFD | Y2: FULLY WIN CORPORATION LIMITED | Z2: FULLY WIN CORPORATION LIMITED | AA2: 4790.09 | AB2: LCH05 | AC2: HKG03
A3: BEAU2356127 | B3: 2026-10-08 | C3: SWDN | D3: 2610N | E3: 22GP | F3: SD | G3: THLCH | H3: THLCH | I3: CNXMN | J3: CNXMN | K3: F | L3: L/T | M3: VFL | N3: LCH05 | O3: LCH | P3: TH | Q3: HASLS22260901146 | R3: N | S3: N | T3: CHT | V3: TSN16L05 | W3: PTT GLOBAL CHEMICAL PUBLIC COMPANY | X3: VFD | Y3: SINOCHEM PETROCHEMICAL | Z3: SINOCHEM INTERNATIONAL OIL | AA3: 18072 | AB3: LCH05 | AC3: XMN01
A4: BEAU2477638 | B4: 2026-10-08 | C4: SWDN | D4: 2610N | E4: 22GP | F4: SD | G4: THLCH | H4: THLCH | I4: CNXMN | J4: CNXMN | K4: F | L4: L/T | M4: VFL | N4: LCH05 | O4: LCH | P4: TH | Q4: HASLS22260901029 | R4: N | S4: N | T4: CHT | V4: SHA16L07 | W4: THAI POLYCARBONATE CO.,LTD. | X4: VFD | Y4: PLASTEL INDUSTRIES CO.,LTD. | Z4: PLASTEL INDUSTRIES CO.,LTD. | AA4: 16432 | AB4: LCH05 | AC4: XMN01
A5: BEAU2985449 | B5: 2026-10-08 | C5: SWDN | D5: 2610N | E5: 22GP | F5: SD | G5: THLCH | H5: THLCH | I5: CNXMN | J5: CNXMN | K5: F | L5: L/T | M5: VFL | N5: LCH05 | O5: LCH | P5: TH | Q5: HASLS22260901873 | R5: N | S5: N | T5: CHT | V5: SHA17L01 | W5: DIMERCO EXPRESS (THAILAND) CO.,LTD. | X5: VED | Y5: DIVERSIFIED INTERNATIONAL | Z5: DIVERSIFIED INTERNATIONAL | AA5: 542.8 | AB5: LCH05 | AC5: XMN01
A6: FBIU5092414 | B6: 2026-10-08 | C6: SWDN | D6: 2610N | E6: 45RE | F6: SD | G6: THLCH | H6: THLCH | I6: HKHKG | J6: HKHKG | K6: F | L6: ONE | M6: VFL | N6: LCH05 | O6: LCH | P6: TH | Q6: HASLS22260902204 | R6: N | S6: N | T6: CHT | V6: K0120025 | W6: AN NAM DRAGON 2017 CO.,LTD. | X6: VFD | Y6: XIN THAI XIANG IMPORTS AND EXPORTS | Z6: XIN THAI XIANG IMPORTS AND EXPORTS | AA6: 22194.3 | AB6: LCH05 | AC6: HKG03
A7: FBIU5103210 | B7: 2026-10-08 | C7: SWDN | D7: 2610N | E7: 45RE | F7: SD | G7: THLCH | H7: THLCH | I7: HKHKG | J7: HKHKG | K7: F | L7: L/T | M7: VFL | N7: LCH05 | O7: LCH | P7: TH | Q7: HASLS22260801601 | R7: N | S7: N | T7: CHT | V7: C0321002 | W7: CP-MEIJI CO.,LTD. | X7: VFD | Y7: CPF HONG KONG COMPANY LIMITED | Z7: CPF HONG KONG COMPANY LIMITED | AA7: 23084.88 | AB7: LCH05 | AC7: HKG03
A8: FBIU5103313 | B8: 2026-10-08 | C8: SWDN | D8: 2610N | E8: 45RE | F8: SD | G8: THLCH | H8: THLCH | I8: HKHKG | J8: HKHKG | K8: F | L8: L/T | M8: VFL | N8: LCH05 | O8: LCH | P8: TH | Q8: HASLS22260900917 | R8: N | S8: N | T8: CHT | V8: C0321002 | W8: CP-MEIJI CO.,LTD. | X8: VFD | Y8: CPF HONG KONG COMPANY LIMITED | Z8: CPF HONG KONG COMPANY LIMITED | AA8: 21182.28 | AB8: LCH05 | AC8: HKG03
A9: FSCU5893590 | B9: 2026-10-08 | C9: SWDN | D9: 2610N | E9: 45RE | F9: SD | G9: THLCH | H9: THLCH | I9: HKHKG | J9: HKHKG | K9: F | L9: L/T | M9: VFL | N9: LCH05 | O9: LCH | P9: TH | Q9: HASLS22260900918 | R9: N | S9: N | T9: CHT | V9: C0320021 | W9: CP-MEIJI CO.,LTD. | X9: VFD | Y9: CPF HONG KONG COMPANY LIMITED | Z9: CPF HONG KONG COMPANY LIMITED | AA9: 23655.66 | AB9: LCH05 | AC9: HKG03
A10: GCXU2429912 | B10: 2026-10-08 | C10: SWDN | D10: 2610N | E10: 22GP | F10: SD | G10: THLCH | H10: THLCH | I10: HKHKG | J10: HKHKG | K10: F | L10: ONE | M10: VFL | N10: LCH05 | O10: LCH | P10: TH | Q10: HASLS22260800649 | R10: N | S10: N | T10: CHT | V10: K0120021 | W10: NIPPON EXPRESS LOGISTICS | X10: VFD | Y10: NIPPON EXPRESS (H.K.) CO.,LTD. | Z10: NIPPON EXPRESS (H.K.) CO.,LTD. | AA10: 1046 | AB10: LCH05 | AC10: HKG03
A11: HALU2083638 | B11: 2026-10-08 | C11: SWDN | D11: 2610N | E11: 22GP | F11: SD | G11: THLCH | H11: THLCH | I11: CNXMN | J11: CNXMN | K11: F | L11: OWN | M11: VFL | N11: LCH05 | O11: LCH | P11: TH | Q11: HASLS22260901415 | R11: N | S11: N | T11: CHT | V11: TXG15006 | W11: SCGC ICO POLYMERS CO.,LTD. | X11: VED | Y11: SHANGHAI JIUCHENG TRADE CO., LTD. | Z11: SHANGHAI JIUCHENG TRADE CO., LTD. | AA11: 11265.2 | AB11: LCH05 | AC11: XMN01
A12: HALU2313129 | B12: 2026-10-08 | C12: SWDN | D12: 2610N | E12: 22GP | F12: SD | G12: THLCH | H12: THLCH | I12: HKHKG | J12: CNZHU | K12: F | L12: OWN | M12: VFL | N12: LCH05 | O12: LCH | P12: TH | Q12: HASLS22260900563 | R12: N | S12: N | T12: CHT | V12: C0223001 | W12: PTT GLOBAL CHEMICAL PUBLIC COMPANY | X12: VED | Y12: GC MARKETING SOLUTIONS (SHANGHAI) | Z12: GC MARKETING SOLUTIONS (SHANGHAI) | AA12: 18072 | AB12: LCH05 | AC12: HKG03
A13: HALU2352969 | B13: 2026-10-08 | C13: SWDN | D13: 2610N | E13: 22GP | F13: SD | G13: THLCH | H13: THLCH | I13: CNXMN | J13: CNXMN | K13: F | L13: OWN | M13: VFL | N13: LCH05 | O13: LCH | P13: TH | Q13: HASLS22260901146 | R13: N | S13: N | T13: CHT | V13: C0223008 | W13: PTT GLOBAL CHEMICAL PUBLIC COMPANY | X13: VED | Y13: SINOCHEM PETROCHEMICAL | Z13: SINOCHEM INTERNATIONAL OIL | AA13: 18072 | AB13: LCH05 | AC13: XMN01
... A48: SKLU3510078 | B48: 2026-10-08 | C48: SWDN | D48: 2610N | E48: 22GP | F48: SD | G48: THLCH | H48: THLCH | I48: CNXMN | J48: CNXMN | K48: F | L48: ONE | M48: VFL | N48: LCH05 | O48: LCH | P48: TH | Q48: HASLS22260901146 | R48: N | S48: N | T48: CHT | V48: K0120021 | W48: PTT GLOBAL CHEMICAL PUBLIC COMPANY | X48: VFD | Y48: SINOCHEM PETROCHEMICAL | Z48: SINOCHEM INTERNATIONAL OIL | AA48: 18072 | AB48: LCH05 | AC48: XMN01
AA49: 835588.77

Sheet 2.Bookinglist
A1: B/K No | B1: Cntr Type & Size | C1: Pickup | D1: CY Return | E1: RCVCD | F1: C10 | G1: C20 | H1: C40 | I1: C45 | J1: TEU | K1: SOC | L1: SVC | M1: VSL | N1: VOY | O1: POL | P1: LWharf | Q1: LAREA | R1: ETD | S1: POD | T1: DWharf | U1: Delivery | V1: ETA | W1: DAREA | X1: Inland | Y1: T/S WHARF | Z1: TS PORT | AA1: Shipper | AB1: Org Shipper | AC1: BKG WGT | AD1: BK Tot Weight | AE1: Cntr Compare | AF1: SR | AG1: PKG | AH1: EL | AI1: CHK | AJ1: TRAFFIC | AK1: DocumentID | AL1: Document | AM1: SALESCD | AN1: SALESNM | AO1: Main Item | AP1: B/K Type | AQ1: DG | AR1: DGCNT | AS1: RF | AT1: RFCNT | AU1: AWK | AV1: AWKCNT | AW1: AWKVOID | AX1: FLEXIBAG | AY1: BLISSUE | AZ1: Remark | BA1: OFFICERMK | BB1: PAY TERM | BC1: Input Date | BD1: Update Date | BE1: Status | BF1: Commodity | BG1: Self Trans | BH1: Booking Loc | BI1: Trans Code | BJ1: Trans Name | BK1: Pickup | BL1: Pickup Date | BM1: 12GP | BN1: 22GP | BO1: 42GP | BP1: 45GP | BQ1: 22RE | BR1: 45RE | BS1: 22UT | BT1: 42UT | BU1: 22PC | BV1: 42PC | BW1: 22TN | BX1: 42TN | BY1: FE | BZ1: STAY | CA1: WEB | CB1: Special Remark | CC1: Return | CD1: Over WGT | CE1: VGM ERR MSG | CF1: CLASS(DG) TEU | CG1: CGO TERM | CH1: T/S Info | CI1: Email | CJ1: Shipper | CK1: Consignee | CL1: Notify | CM1: B/L Close | CN1: DOC_CLOSE | CO1: CNTR_CLOSE | CP1: Special Info. | CQ1: TARIFF REF | CR1: TARIFF CUSTOMER | CS1: TARIFF CUSTOMER NAME | CT1: Split | CU1: DG App Mail | CV1: Cas No. | CW1: CUST ETD | CX1: HSCODE | CY1: Roll Over Remark
A2: HASLS22260900990 | B2: 20RFx1 | C2: 1 | D2: 1 | E2: THLKR | F2: 0 | G2: 1 | H2: 0 | I2: 0 | J2: 1 | K2: N | L2: CHT | M2: SWDN | N2: 2610N | O2: THLCH | P2: LCH05 | Q2: IA | R2: 2026-10-08 | S2: HKHKG | T2: HKG03 | U2: HKHKG | V2: 2026-10-11 | W2: IA | AA2: NAMYONG LOGISTICS CO., LTD. | AB2: THAI SUMMIT MARKETING CO., LTD. | AC2: 4790.09 | AD2: 6990.09 | AE2: OK | AH2: CHK | AI2: OK | AM2: TBKK47 | AN2: Tarn(Supaporn) | AO2: FROZEN CHICKEN MEAT / FROZEN PREPARED CHICKEN MEAT | AP2: T/S | AS2: RF// MIN:-20.0 MAX:-20.0 [COVER:CLOSE] | AT2: 22REx1 | AW2: 0 | AX2: N | AY2: OBL | AZ2: Pickup : 2026-09-28, Return LKR : 2026-09-30 (Temp -20.0 / Vent Close) [PAPERLESS CODE 2815] CLS TIME 01/10/26 @23.59 (1ST DATE RTN 30/09/2026 W/O RENT,ELECTRIC) | BA2: FM KMGY 2610N 11/09HS CODE: 1602.32 | BB2: P | BC2: 2026-09-11 | BD2: 2026-10-01 | BE2: Y | BF2: FROZEN CHICKEN MEAT | BG2: Line | BH2: S22 | BK2: BKK27 | BL2: 2026-09-28 | BQ2: 1 | BY2: FULL | CA2: Y | CC2: LCH55 | CF2: 0 Teu | CG2: CY/CY | CI2: op-seaex@namyonglogistics.com | CJ2: THAI SUMMIT MARKETING CO., LTD. | CK2: FULLY WIN CORPORATION LIMITED | CL2: FULLY WIN CORPORATION LIMITED | CM2: CLOSED | CN2: 202610051200 | CO2: 202610061500 | CP2: 22RE x1: RF(Temp:-20.0' / Cover:CLOSE) | CQ2: S22-2308029 | CR2: THTKGC | CS2: NAMYONG LOGISTICS CO., LTD. | CT2: N | CW2: 2026-10-03
A3: HASLS22260901167 | B3: 20TKx2 | C3: 0 | D3: 0 | F3: 0 | G3: 2 | H3: 0 | I3: 0 | J3: 2 | K3: SOC | L3: CHT | M3: SWDN | N3: 2610N | O3: THLCH | P3: LCH05 | Q3: IA | R3: 2026-10-08 | S3: HKHKG | T3: HKG03 | U3: CNHUA | V3: 2026-10-11 | W3: IA | X3: Barge | AA3: NS INTERNATIONAL (THAILAND) CO., LTD. | AB3: THAI MMA CO., LTD. | AC3: 43810 | AD3: 51810 | AE3: OK | AF3: SR | AH3: CHK | AM3: TBKK97 | AN3: Arunphat W. (Aiw) | AO3: METHACRYLIC ACID (MAA) | AP3: Normal | AQ3: 2531/8-II | AR3: 22TNx2 | AW3: 0 | AX3: N | AZ3: **APPROVE DG IN SYSTEM 18/09/26** DG22TNx2 (CLS 8 / UN 2531) SOC Pickup : 2026-09-24, Return @JWD : 2026-09-25 CUSTOMS FORMALITY (SOC) BY NS // Tax ID : 0105550071991 | BA3: CUSTOMS FORMALITY (SOC) BY NS // Tax ID : 0105550071991 | BB3: P | BC3: 2026-09-15 | BD3: 2026-10-05 | BE3: Y | BF3: METHACRYLIC ACID (MAA) | BG3: Line | BH3: S22 | BL3: 2026-09-24 | BW3: 2 | BY3: FULL | CA3: Y | CC3: LCH05 | CF3: 8 Class x 2 Teu (Approval), | CG3: CY/CY | CI3: EXPORT@NSINTER.COM | CJ3: NS INTERNATIONAL (THAILAND) CO.,LTD | CK3: DL CHEMICAL YIBIANSHI(SHANGHAI) | CL3: DL CHEMICAL YIBIANSHI(SHANGHAI) | CN3: 202610051200 | CO3: 202610061500 | CP3: 22TN x2: DG(UNNo.:2531/ Class:8) | CQ3: S22-2606035 | CR3: TH05FO | CS3: NS INTERNATIONAL (THAILAND) CO., LTD. | CT3: N | CW3: 2026-10-01
A4: HASLS22260900777 | B4: 20'x1 | C4: 1 | D4: 1 | F4: 0 | G4: 1 | H4: 0 | I4: 0 | J4: 1 | K4: N | L4: CHT | M4: SWDN | N4: 2610N | O4: THLCH | P4: LCH05 | Q4: IA | R4: 2026-10-08 | S4: KRINC | T4: INC03 | U4: KRINC | V4: 2026-10-16 | W4: KR | AA4: T.C.PHARMACEUTICAL INDUSTRIES CO., LTD. | AB4: T.C.PHARMACEUTICAL INDUSTRIES CO., LTD. | AC4: 16718.4 | AD4: 18918.4 | AE4: OK | AH4: CHK | AI4: OK | AM4: S1951 | AN4: Lee suk hyun | AO4: SPONSOR ORIGINAL | AP4: Normal | AW4: 0 | AX4: N | AY4: OBL | AZ4: CY-RTN : 02-03/10/2026 PO : 20260824WKTCP05 | BA4: SI DD.29/9/26 | BB4: C | BC4: 2026-09-09 | BD4: 2026-09-29 | BE4: Y | BF4: ELECTROLYTE DRINK | BG4: Line | BH4: S22 | BK4: LCHY5 | BL4: 2026-10-02 | BN4: 1 | BY4: FULL | CC4: LCH05 | CF4: 0 Teu | CG4: CY/CY | CI4: ammarin.phu@tcp.com | CJ4: T.C. PHARMACEUTICAL INDUSTRIES | CK4: WORL-KET COMPANY LIMITED | CL4: WORL-KET COMPANY LIMITED | CM4: CLOSED | CN4: 202610051200 | CO4: 202610061500 | CQ4: K01-2001365 | CR4: THTNWG | CS4: T.C.PHARMACEUTICAL INDUSTRIES CO., LTD. | CT4: N | CW4: 2026-10-03
A5: HASLS22260901415 | B5: 20'x1 | C5: 1 | D5: 1 | F5: 0 | G5: 1 | H5: 0 | I5: 0 | J5: 1 | K5: N | L5: CHT | M5: SWDN | N5: 2610N | O5: THLCH | P5: LCH05 | Q5: IA | R5: 2026-10-08 | S5: CNXMN | T5: XMN01 | U5: CNXMN | V5: 2026-10-13 | W5: IA | AA5: SCGJWD LOGISTICS PUBLIC COMPANY LIMITED | AB5: THAI POLYETHYLENE CO., LTD. | AC5: 11265.2 | AD5: 13465.2 | AE5: OK | AF5: SR | AH5: CHK | AI5: OK | AM5: TBKK19 | AN5: Kanokporn | AO5: LINEAR LOW DENSITY POLYETHYLENE RESIN | AP5: Normal | AW5: 0 | AX5: N | AY5: OBL | AZ5: CY-RTN : 21-22/09/2026 **INV : 3231006655 REQ GOOD AND CLEAN CONT., NO OIL, NO RUSTY | BA5: ROLL OVER FROM PREVIOUS VSL KMGY 2610N BY ALLOCATION TEAM MS.TARN APPROVED COST IS UNDER HAL DD.28/09 | BB5: P | BC5: 2026-09-16 | BD5: 2026-10-01 | BE5: Y | BF5: RESIN | BG5: Line | BH5: S22 | BK5: LCHY5 | BL5: 2026-09-21 | BN5: 1 | BY5: FULL | CC5: LCH05 | CF5: 0 Teu | CG5: CY/CY | CI5: pornnariv@scgjwd.com | CJ5: SCGC ICO POLYMERS CO.,LTD. | CK5: SHANGHAI JIUCHENG TRADE CO., LTD. | CL5: SHANGHAI JIUCHENG TRADE CO., LTD. | CM5: CLOSED | CN5: 202610051200 | CO5: 202610061500 | CQ5: S19-2308041 | CR5: TH0235 | CS5: SCGJWD LOGISTICS PUBLIC COMPANY LIMITED | CT5: N | CW5: 2026-10-07 | CX5: 390140 | CY5: ROLL OVER FROM PREVIOUS VSL KMGY 2610N BY ALLOCATION TEAM MS.TARN APPROVED COST IS UNDER HAL DD.28/09
A6: HASLS22260901873 | B6: 20'x1 | C6: 1 | D6: 1 | F6: 0 | G6: 1 | H6: 0 | I6: 0 | J6: 1 | K6: N | L6: CHT | M6: SWDN | N6: 2610N | O6: THLCH | P6: LCH05 | Q6: IA | R6: 2026-10-08 | S6: CNXMN | T6: XMN01 | U6: CNXMN | V6: 2026-10-13 | W6: IA | AA6: DIMERCO EXPRESS (THAILAND) CO., LTD. | AB6: MITSUBISHI ELECTRIC THAI AUTO-PARTS CO., LTD. | AC6: 542.8 | AD6: 2742.8 | AE6: OK | AF6: SR | AH6: CON | AI6: OK | AM6: TBKK28 | AN6: Nustsireerach | AO6: ASSY-LCD | AP6: Normal | AW6: 0 | AX6: N | AY6: OBL | AZ6: Pickup : 2026-09-28, Return : 2026-09-29 (1ST RTN 29/09 W/O RENT) ** PLEASE CHECK OPEN GATE BEFORE RETURN CNTR ** | BA6: FM KMGY 2610N DD 22/09 | BB6: P | BC6: 2026-09-21 | BD6: 2026-10-01 | BE6: Y | BF6: ASSY-LCD | BG6: Line | BH6: S22 | BK6: LCHY5 | BL6: 2026-09-28 | BN6: 1 | BY6: FULL | CA6: Y | CC6: LCH05 | CF6: 0 Teu | CG6: CY/CY | CI6: oe_dimbkk@dimerco.com | CJ6: DIMERCO EXPRESS (THAILAND) CO.,LTD. | CK6: DIVERSIFIED INTERNATIONAL | CL6: DIVERSIFIED INTERNATIONAL | CM6: CLOSED | CN6: 202610051200 | CO6: 202610061500 | CQ6: S19-2307006 | CR6: BB0164 | CS6: DIMERCO EXPRESS (THAILAND) CO., LTD. | CT6: N | CW6: 2026-10-03
A7: HASLS22260902542 | B7: 20'x1 | C7: 1 | D7: 1 | F7: 0 | G7: 1 | H7: 0 | I7: 0 | J7: 1 | K7: N | L7: CHT | M7: SWDN | N7: 2610N | O7: THLCH | P7: LCH05 | Q7: IA | R7: 2026-10-08 | S7: KRINC | T7: INC03 | U7: KRINC | V7: 2026-10-16 | W7: KR | AA7: MAXTOP LOGISTICS (THAILAND) CO., LTD. | AB7: ALLIANCE LAUNDRY (THAILAND) CO., LTD. | AC7: 1920.962 | AD7: 4120.962 | AE7: OK | AF7: SR | AH7: CHK | AI7: OK | AM7: TBKK97 | AN7: Arunphat W. (Aiw) | AO7: SELF SERVICE WASHERS AND TUMBLE DRYERS | AP7: Normal | AW7: 0 | AX7: N | AY7: OBL | AZ7: Pickup : 2026-10-01, Return : 2026-10-03 *1ST RETURN CNTR DD.03/10/2026* ** PLEASE CHECK OPEN GATE BEFORE RETURN CNTR ** | BB7: P | BC7: 2026-09-28 | BD7: 2026-10-02 | BE7: Y | BF7: SELF SERVICE WASHERS AND TUMBLE DRYERS | BG7: Line | BH7: S22 | BK7: LCHY5 | BL7: 2026-10-01 | BN7: 1 | BY7: FULL | CA7: Y | CC7: LCH05 | CF7: 0 Teu | CG7: CY/CY | CI7: maxtop.thai@maxlogis.com | CJ7: MAXTOP LOGISTICS(THAILAND)CO.,LTD. | CK7: CHEONWOO NEOLOGIS CO.,LTD. | CL7: CHEONWOO NEOLOGIS CO.,LTD. | CM7: CLOSED | CN7: 202610051200 | CO7: 202610061500 | CQ7: S22-2602020 | CR7: THTTF4 | CS7: MAXTOP LOGISTICS (THAILAND) CO., LTD. | CT7: N | CW7: 2026-10-07
A8: HASLS22260800649 | B8: 20'x1 | C8: 1 | D8: 1 | F8: 0 | G8: 1 | H8: 0 | I8: 0 | J8: 1 | K8: N | L8: CHT | M8: SWDN | N8: 2610N | O8: THLCH | P8: LCH05 | Q8: IA | R8: 2026-10-08 | S8: HKHKG | T8: HKG03 | U8: HKHKG | V8: 2026-10-11 | W8: IA | AA8: NIPPON EXPRESS LOGISTICS (THAILAND) CO., LTD. | AB8: OLYMPUS(THAILAND) CO., LTD. | AC8: 1046 | AD8: 3246 | AE8: OK | AH8: CON | AI8: OK | AM8: 440007 | AN8: AHN SOON BO | AO8: OTHER INSTRUMENTS IN MEDICAL, SURGICAL, | AP8: Normal | AW8: 0 | AX8: N | AY8: OBL | AZ8: Pickup : 2026-09-24, Return : 2026-09-25 [1ST RTN 29/09/2026 W/O RENT] ** PLEASE CHECK OPEN GATE BEFORE RETURN CONTAINER ** ADD DEM COST 4 DAYS = 1,500 BAHT | BA8: ADD DEM COST 4 DAYS = 1,500 BAHT CUST. ACCEPT DD 25/09 MAINTAIN SWDN 2610N BY K.POON DD 23/09 FM SWSR 2611N 07/09 FM 1X40HQ 15/09 FM SKOR 2611N DD 17/09 B/L Type SEA WAYBILL | BB8: P | BC8: 2026-08-07 | BD8: 2026-10-05 | BE8: Y | BF8: OTHER INSTRUMENTS IN MEDICAL, SURGICAL, | BG8: Line | BH8: S22 | BK8: LCHY5 | BL8: 2026-09-24 | BN8: 1 | BY8: FULL | CA8: Y | CC8: LCH05 | CF8: 0 Teu | CG8: CY/CY | CI8: NELT-aclc-exp@nipponexpress.com | CJ8: NIPPON EXPRESS LOGISTICS | CK8: NIPPON EXPRESS (H.K.) CO.,LTD. | CL8: NIPPON EXPRESS (H.K.) CO.,LTD. | CM8: CLOSED | CN8: 202610051200 | CO8: 202610061500 | CQ8: K01-2604098 | CR8: THTSOT | CS8: NIPPON EXPRESS LOGISTICS (THAILAND) CO., LTD. | CT8: N | CW8: 2026-10-03
A9: HASLS22260901015 | B9: 20'x1 | C9: 1 | D9: 1 | F9: 0 | G9: 1 | H9: 0 | I9: 0 | J9: 1 | K9: N | L9: CHT | M9: SWDN | N9: 2610N | O9: THLCH | P9: LCH05 | Q9: IA | R9: 2026-10-08 | S9: CNXMN | T9: XMN01 | U9: CNXMN | V9: 2026-10-13 | W9: IA | AA9: THAI POLYCARBONATE CO., LTD. | AB9: THAI POLYCARBONATE CO., LTD. | AC9: 16672 | AD9: 18872 | AE9: OK | AH9: CHK | AI9: OK | AM9: TBKK55 | AN9: Vilaiporn | AO9: POLYCARBONATE RESIN IUPILON | AP9: Normal | AW9: 0 | AX9: N | AY9: OBL | AZ9: Pickup : 2026-09-24, Return : 2026-09-25 (1ST RTN 26/09 W/O RENT) ** PLEASE CHECK OPEN GATE BEFORE RETURN CNTR ** | BA9: SI DD.18/9/26 | BB9: P | BC9: 2026-09-11 | BD9: 2026-09-18 | BE9: Y | BF9: POLYCARBONATE RESIN , HS CODEIS 3907.40 | BG9: Line | BH9: S22 | BK9: LCH27 | BL9: 2026-09-24 | BN9: 1 | BY9: FULL | CA9: Y | CC9: LCH05 | CF9: 0 Teu | CG9: CY/CY | CI9: supaporn.fako@th.tpcc-tpac.com | CJ9: THAI POLYCARBONATE CO.,LTD. | CK9: DONG GUAN HUA GANG INTERNATIONAL | CL9: DONG GUAN HUA GANG INTERNATIONAL | CM9: CLOSED | CN9: 202610051200 | CO9: 202610061500 | CQ9: S19-2112039 | CR9: THTKNC | CS9: THAI POLYCARBONATE CO., LTD. | CT9: N | CW9: 2026-09-30 | CX9: 390740
A10: HASLS22260901029 | B10: 20'x3 | C10: 3 | D10: 3 | F10: 0 | G10: 3 | H10: 0 | I10: 0 | J10: 3 | K10: N | L10: CHT | M10: SWDN | N10: 2610N | O10: THLCH | P10: LCH05 | Q10: IA | R10: 2026-10-08 | S10: CNXMN | T10: XMN01 | U10: CNXMN | V10: 2026-10-13 | W10: IA | AA10: THAI POLYCARBONATE CO., LTD. | AB10: THAI POLYCARBONATE CO., LTD. | AC10: 49296 | AD10: 55896 | AE10: OK | AH10: CHK | AI10: OK | AM10: TBKK55 | AN10: Vilaiporn | AO10: POLYCARBONATE RESIN IUPILON | AP10: Normal | AW10: 0 | AX10: N | AY10: OBL | AZ10: Pickup : 2026-09-23, Return : 2026-09-25 [1ST RTN 26/09/2026 W/O RENT] ** PLEASE CHECK OPEN GATE BEFORE RETURN CONTAINER ** | BA10: SI DD.25/9/26 | BB10: P | BC10: 2026-09-11 | BD10: 2026-09-25 | BE10: Y | BF10: POLYCARBONATE RESIN (HS CODE. 3907.40) | BG10: Line | BH10: S22 | BK10: LCH27 | BL10: 2026-09-23 | BN10: 3 | BY10: FULL | CA10: Y | CC10: LCH05 | CF10: 0 Teu | CG10: CY/CY | CI10: supaporn.fako@th.tpcc-tpac.com | CJ10: THAI POLYCARBONATE CO.,LTD. | CK10: PLASTEL INDUSTRIES CO.,LTD. | CL10: PLASTEL INDUSTRIES CO.,LTD. | CM10: CLOSED | CN10: 202610051200 | CO10: 202610061500 | CQ10: S19-2112039 | CR10: THTKNC | CS10: THAI POLYCARBONATE CO., LTD. | CT10: N | CW10: 2026-09-30 | CX10: 390740
A11: HASLS22260901146 | B11: 20'x4 | C11: 4 | D11: 4 | F11: 0 | G11: 4 | H11: 0 | I11: 0 | J11: 4 | K11: N | L11: CHT | M11: SWDN | N11: 2610N | O11: THLCH | P11: LCH05 | Q11: IA | R11: 2026-10-08 | S11: CNXMN | T11: XMN01 | U11: CNXMN | V11: 2026-10-13 | W11: IA | AA11: WHA GC LOGISTICS COMPANY LIMITED | AB11: PTT GLOBAL CHEMICAL PUBLIC COMPANY LIMITED | AC11: 72288 | AD11: 81088 | AE11: OK | AH11: CHK | AI11: OK | AM11: TBKK13 | AN11: Dharaporn | AO11: LINEAR LOW DENSITY POLYETHYLENE | AP11: Normal | AW11: 0 | AX11: N | AZ11: CY-RTN 21-25/09/26 *PR2610003144* | BA11: SI DD.21/9/26 | BB11: P | BC11: 2026-09-14 | BD11: 2026-10-01 | BE11: Y | BF11: RESIN | BG11: Line | BH11: S22 | BK11: LCHY5 | BL11: 2026-09-21 | BN11: 4 | BY11: FULL | CC11: LCH05 | CF11: 0 Teu | CG11: CY/CY | CI11: nitchakamon.s@wha-gc.com | CJ11: PTT GLOBAL CHEMICAL PUBLIC COMPANY | CK11: SINOCHEM PETROCHEMICAL | CL11: SINOCHEM INTERNATIONAL OIL | CN11: 202610051200 | CO11: 202610061500 | CQ11: S22-2309036 | CR11: TH02GR | CS11: WHA GC LOGISTICS COMPANY LIMITED | CT11: N | CW11: 2026-10-01 | CX11: 390140
A12: HASLS22260901148 | B12: 20'x4 | C12: 4 | D12: 4 | F12: 0 | G12: 4 | H12: 0 | I12: 0 | J12: 4 | K12: N | L12: CHT | M12: SWDN | N12: 2610N | O12: THLCH | P12: LCH05 | Q12: IA | R12: 2026-10-08 | S12: CNXMN | T12: XMN01 | U12: CNXMN | V12: 2026-10-13 | W12: IA | AA12: WHA GC LOGISTICS COMPANY LIMITED | AB12: PTT GLOBAL CHEMICAL PUBLIC COMPANY LIMITED | AC12: 72288 | AD12: 81088 | AE12: OK | AH12: CHK | AI12: OK | AM12: TBKK13 | AN12: Dharaporn | AO12: LINEAR LOW DENSITY POLYETHYLENE | AP12: Normal | AW12: 0 | AX12: N | AZ12: CY-RTN 21-25/09/26 *PR2610003148* | BA12: SI DD.21/9/26 | BB12: P | BC12: 2026-09-14 | BD12: 2026-10-01 | BE12: Y | BF12: RESIN | BG12: Line | BH12: S22 | BK12: LCHY5 | BL12: 2026-09-21 | BN12: 4 | BY12: FULL | CC12: LCH05 | CF12: 0 Teu | CG12: CY/CY | CI12: nitchakamon.s@wha-gc.com | CJ12: PTT GLOBAL CHEMICAL PUBLIC COMPANY | CK12: LEMIBA (QUANZHOU) NEW MATERIAL | CL12: LEMIBA (QUANZHOU) NEW MATERIAL | CN12: 202610051200 | CO12: 202610061500 | CQ12: S22-2309036 | CR12: TH02GR | CS12: WHA GC LOGISTICS COMPANY LIMITED | CT12: N | CW12: 2026-10-01 | CX12: 390140
A13: HASLS22260900563 | B13: 20'x8 | C13: 8 | D13: 8 | F13: 0 | G13: 8 | H13: 0 | I13: 0 | J13: 8 | K13: N | L13: CHT | M13: SWDN | N13: 2610N | O13: THLCH | P13: LCH05 | Q13: IA | R13: 2026-10-08 | S13: HKHKG | T13: HKG03 | U13: CNZHU | V13: 2026-10-11 | W13: IA | X13: Barge | AA13: WHA GC LOGISTICS COMPANY LIMITED | AB13: PTT GLOBAL CHEMICAL PUBLIC COMPANY LIMITED | AC13: 144576 | AD13: 162176 | AE13: OK | AH13: CHK | AI13: OK | AM13: TBKK13 | AN13: Dharaporn | AO13: HIGH DENSITY POLYETHYLENE (HDPE) | AP13: Normal | AW13: 0 | AX13: N | AZ13: CY-RTN 21-25/09/26 (CIVET TERMINAL) *PLS CHECK OPEN GATE BEFORE RETURN CTNR* | BA13: SI DD.21/9/26 (CIVET TERMINAL) CNTR: HALU2400286/HAL458661 , SKLU1661500/HAL458662 MOVE FM HASLS22260900583 | BB13: P | BC13: 2026-09-07 | BD13: 2026-09-28 | BE13: Y | BF13: RESIN | BG13: Line | BH13: S22 | BK13: LCH27 | BL13: 2026-09-21 | BN13: 8 | BY13: FULL | CC13: LCH05 | CF13: 0 Teu | CG13: CY/CY | CI13: jariya.c@wha-gc.com | CJ13: PTT GLOBAL CHEMICAL PUBLIC COMPANY | CK13: GC MARKETING SOLUTIONS (SHANGHAI) | CL13: GC MARKETING SOLUTIONS (SHANGHAI) | CN13: 202610051200 | CO13: 202610061500 | CQ13: S22-2309036 | CR13: TH02GR | CS13: WHA GC LOGISTICS COMPANY LIMITED | CT13: N | CW13: 2026-09-30 | CX13: 390120
A14: HASLS22260902174 | B14: 40Hx1 | C14: 1 | D14: 1 | F14: 0 | G14: 0 | H14: 0 | I14: 1 | J14: 2 | K14: N | L14: CHT | M14: SWDN | N14: 2610N | O14: THLCH | P14: LCH05 | Q14: IA | R14: 2026-10-08 | S14: KRINC | T14: INC03 | U14: KRINC | V14: 2026-10-16 | W14: KR | AA14: LX PANTOS (THAILAND) CO., LTD. | AB14: ROFU (THAILAND) LTD. | AC14: 5699.96 | AD14: 9699.96 | AE14: OK | AH14: CHK | AI14: OK | AM14: H2602 | AN14: Kim jaewon | AO14: SHOES | AP14: Normal | AW14: 0 | AX14: N | AZ14: Pickup : 2026-09-28, Return : 2026-09-29 | BA14: SI | BB14: C | BC14: 2026-09-23 | BD14: 2026-10-02 | BE14: Y | BF14: SHOES KEEN BRAND | BG14: Line | BH14: S22 | BK14: LCHY5 | BL14: 2026-09-28 | BP14: 1 | BY14: FULL | CA14: Y | CC14: LCH05 | CF14: 0 Teu | CG14: CY/CY | CI14: th.seaopenex@lxpantos.com | CJ14: LX PANTOS (THAILAND) CO., LTD. | CK14: LX PANTOS CO., LTD. | CL14: LX PANTOS CO., LTD. | CN14: 202610051200 | CO14: 202610061500 | CQ14: K01-2112121 | CR14: THTRJ5 | CS14: LX PANTOS (THAILAND) CO., LTD. | CT14: N | CW14: 2026-10-03
A15: HASLS22260800648 | B15: 40Hx1 | C15: 1 | D15: 1 | F15: 0 | G15: 0 | H15: 0 | I15: 1 | J15: 2 | K15: N | L15: CHT | M15: SWDN | N15: 2610N | O15: THLCH | P15: LCH05 | Q15: IA | R15: 2026-10-08 | S15: HKHKG | T15: HKG03 | U15: HKHKG | V15: 2026-10-11 | W15: IA | AA15: NIPPON EXPRESS LOGISTICS (THAILAND) CO., LTD. | AB15: OLYMPUS(THAILAND) CO., LTD. | AC15: 6330 | AD15: 10330 | AE15: OK | AF15: SR | AH15: CON | AI15: OK | AM15: 440007 | AN15: AHN SOON BO | AO15: OTHER INSTRUMENTS IN MEDICAL, SURGICAL, | AP15: Normal | AW15: 0 | AX15: N | AZ15: Pickup : 2026-09-25, Return : 2026-09-25 (1ST RTN 29/09 W/O RENT) ** PLEASE CHECK OPEN GATE BEFORE RETURN CNTR ** ADD DEM COST 4 DAYS = 3,000 BAHT | BA15: ADD DEM COST 4 DAYS = 3,000 BAHT CUST. CFM DD 25/09 MAINTAIN SWDN 2610N BY K. POON DD 23/09 FM SKOR 2611N DD 17/09 FM CMA 2614N DD 17/08 FM SWSR 2611N 07/09 | BB15: P | BC15: 2026-08-07 | BD15: 2026-10-05 | BE15: Y | BF15: OTHER INSTRUMENTS IN MEDICAL, SURGICAL, | BG15: Line | BH15: S22 | BK15: LCHY5 | BL15: 2026-09-25 | BP15: 1 | BY15: FULL | CA15: Y | CC15: LCH05 | CF15: 0 Teu | CG15: CY/CY | CI15: NELT-aclc-exp@nipponexpress.com | CJ15: NIPPON EXPRESS LOGISTICS | CK15: NIPPON EXPRESS (H.K.) CO.,LTD. | CL15: NIPPON EXPRESS (H.K.) CO.,LTD. | CN15: 202610051200 | CO15: 202610061500 | CQ15: K01-2604098 | CR15: THTSOT | CS15: NIPPON EXPRESS LOGISTICS (THAILAND) CO., LTD. | CT15: N | CW15: 2026-10-03
A16: HASLS22260901529 | B16: 40Hx1 | C16: 1 | D16: 1 | F16: 0 | G16: 0 | H16: 0 | I16: 1 | J16: 2 | K16: N | L16: CHT | M16: SWDN | N16: 2610N | O16: THLCH | P16: LCH05 | Q16: IA | R16: 2026-10-08 | S16: HKHKG | T16: HKG03 | U16: HKHKG | V16: 2026-10-11 | W16: IA | AA16: PGS LOGISTICS (THAILAND) CO., LTD. | AB16: ROFU (THAILAND) LTD. | AC16: 5615.52 | AD16: 9615.52 | AE16: OK | AH16: CHK | AI16: OK | AM16: TBKK97 | AN16: Arunphat W. (Aiw) | AO16: SHOES | AP16: Normal | AW16: 0 | AX16: N | AY16: OBL | AZ16: Pickup : 2026-09-29, Return : 2026-09-30 (1ST 01/10 RETURN W/O RENT) | BA16: ROLL OVER FROM PREVIOUS VSL SWAT 2610N BY ALLOCATION TEAM MS.TARN APPROVED COST IS UNDER HAL DD.05/10 SI DD.5/10/26 COST DEM 1 DAY 750 BAHT AS PER B/L | BB16: P | BC16: 2026-09-17 | BD16: 2026-10-05 | BE16: Y | BF16: SHOES : KEEN BRAND | BG16: Line | BH16: S22 | BK16: LCHY5 | BL16: 2026-09-29 | BP16: 1 | BY16: FULL | CA16: Y | CC16: LCH05 | CF16: 0 Teu | CG16: CY/CY | CI16: bkk-opr@parisigs.com | CJ16: PGS LOGISTICS (THAILAND) CO.,LTD. | CK16: PARISI GRAND SMOOTH LOGISTICS LTD | CL16: PARISI GRAND SMOOTH LOGISTICS LTD | CM16: CLOSED | CN16: 202610051200 | CO16: 202610061500 | CQ16: S22-2609015 | CR16: THTJ7C | CS16: PGS LOGISTICS (THAILAND) CO., LTD. | CT16: N | CW16: 2026-10-08 | CY16: ROLL OVER FROM PREVIOUS VSL SWAT 2610N BY ALLOCATION TEAM MS.TARN APPROVED COST IS UNDER HAL DD.05/10
A17: HASLS22260902144 | B17: 40Hx1 | C17: 1 | D17: 1 | F17: 0 | G17: 0 | H17: 0 | I17: 1 | J17: 2 | K17: N | L17: CHT | M17: SWDN | N17: 2610N | O17: THLCH | P17: LCH05 | Q17: IA | R17: 2026-10-08 | S17: KRINC | T17: INC03 | U17: KRINC | V17: 2026-10-16 | W17: KR | AA17: CANVAS GLOBAL LOGISTICS (THAILAND) CO., LTD. | AB17: SRI TRANG GLOVES (THAILAND) PUBLIC COMPANY LIMITED | AC17: 19555.72 | AD17: 23555.72 | AE17: OK | AH17: CHK | AI17: OK | AM17: TBKK97 | AN17: Arunphat W. (Aiw) | AO17: GLOVES | AP17: Normal | AW17: 0 | AX17: N | AZ17: Pickup : 2026-09-26, Return : 2026-09-28 [1ST RTN 29/09/2026 W/O RENT] ** PLEASE CHECK OPEN GATE BEFORE RETURN CONTAINER ** | BB17: P | BC17: 2026-09-23 | BD17: 2026-09-29 | BE17: Y | BF17: LATEX GLOVES | BG17: Line | BH17: S22 | BK17: LCHY5 | BL17: 2026-09-26 | BP17: 1 | BY17: FULL | CA17: Y | CC17: LCH05 | CF17: 0 Teu | CG17: CY/CY | CI17: cs.log@canvasglobal-log.co.th | CJ17: SRI TRANG GLOVES (THAILAND) PUBLIC | CK17: SEJONG HEALTHCARE CO., LTD | CL17: SEJONG HEALTHCARE CO., LTD | CN17: 202610051200 | CO17: 202610061500 | CQ17: S22-2609010 | CR17: THTWN1 | CS17: CANVAS GLOBAL LOGISTICS (THAILAND) CO., LTD. | CT17: N | CW17: 2026-10-03
A18: HASLS22260902269 | B18: 40Hx1 | C18: 1 | D18: 1 | F18: 0 | G18: 0 | H18: 0 | I18: 1 | J18: 2 | K18: N | L18: CHT | M18: SWDN | N18: 2610N | O18: THLCH | P18: LCH05 | Q18: IA | R18: 2026-10-08 | S18: CNXMN | T18: XMN01 | U18: CNXMN | V18: 2026-10-13 | W18: IA | AA18: COMPREHENSIVE CARGO MANAGEMENT LTD. | AB18: CHAIYA SUWANNABHUM CO.,LTD. | AC18: 26350 | AD18: 30350 | AE18: OK | AH18: CHK | AI18: OK | AM18: TBKK97 | AN18: Arunphat W. (Aiw) | AO18: EXHAUSTED POWDER | AP18: Normal | AW18: 0 | AX18: N | AY18: OBL | AZ18: Pickup : 2026-09-29, Return : 2026-09-30 ** PLEASE CHECK OPEN GATE BEFORE RETURN CNTR ** | BA18: EXPORTER/ CHAIYA SUVARNABHUMI CO.,LTD. | BB18: P | BC18: 2026-09-24 | BD18: 2026-09-30 | BE18: Y | BF18: WOOD POWDER FOR MAKING INCENSE STICK | BG18: Line | BH18: S22 | BK18: LCHY5 | BL18: 2026-09-29 | BP18: 1 | BY18: FULL | CA18: Y | CC18: LCH05 | CF18: 0 Teu | CG18: CY/CY | CI18: ccm@ccmgroups.com | CJ18: CHAIYA SUVARNABHUMI CO.,LTD. | CK18: XIAMEN HONESTY IMPORT AND EXPORT | CL18: XIAMEN HONESTY IMPORT AND EXPORT | CM18: CLOSED | CN18: 202610051200 | CO18: 202610061500 | CQ18: S22-2303004 | CR18: TH016L | CS18: COMPREHENSIVE CARGO MANAGEMENT LTD. | CT18: N | CW18: 2026-10-03
A19: HASLS22260902506 | B19: 40Hx1 | C19: 1 | D19: 1 | F19: 0 | G19: 0 | H19: 0 | I19: 1 | J19: 2 | K19: N | L19: CHT | M19: SWDN | N19: 2610N | O19: THLCH | P19: LCH05 | Q19: IA | R19: 2026-10-08 | S19: HKHKG | T19: HKG03 | U19: HKHKG | V19: 2026-10-11 | W19: IA | AA19: NIPPON EXPRESS LOGISTICS (THAILAND) CO., LTD. | AB19: SLING AUTOMOBILE BEARING (THAILAND) CO.,LTD. | AC19: 17711 | AD19: 21711 | AE19: OK | AF19: SR | AH19: CHK | AI19: OK | AM19: TBKK55 | AN19: Vilaiporn | AO19: BALL BEARING | AP19: Normal | AW19: 0 | AX19: N | AY19: OBL | AZ19: Pickup : 2026-10-02, Return : 2026-10-02 | BA19: FM SHPR: EAS AUTOMOTIVE LTD. 30/09Revise only actual shipper name | BB19: P | BC19: 2026-09-28 | BD19: 2026-09-30 | BE19: Y | BF19: BALL BEARING | BG19: Line | BH19: S22 | BK19: LCH27 | BL19: 2026-10-02 | BP19: 1 | BY19: FULL | CA19: Y | CC19: LCH05 | CF19: 0 Teu | CG19: CY/CY | CI19: nelt-lcb-exp@nipponexpress.com | CJ19: NIPPON EXPRESS LOGISTICS (THAILAND) | CK19: NIPPON EXPRESS (H.K) CO.,LTD | CL19: NIPPON EXPRESS (H.K) CO.,LTD | CM19: CLOSED | CN19: 202610051200 | CO19: 202610061500 | CQ19: S19-2308033 | CR19: THTP3H | CS19: NIPPON EXPRESS LOGISTICS (THAILAND) CO., LTD. | CT19: N | CW19: 2026-10-07
A20: HASLS22260901610 | B20: 40Hx2 | C20: 2 | D20: 2 | F20: 0 | G20: 0 | H20: 0 | I20: 2 | J20: 4 | K20: N | L20: CHT | M20: SWDN | N20: 2610N | O20: THLCH | P20: LCH05 | Q20: IA | R20: 2026-10-08 | S20: KRINC | T20: INC03 | U20: KRINC | V20: 2026-10-16 | W20: KR | AA20: VANACHAI GROUP PUBLIC COMPANY LIMITED | AB20: VANACHAI PANEL INDUSTRIES CO., LTD. | AC20: 48664 | AD20: 56664 | AE20: OK | AH20: CHK | AI20: OK | AM20: TBKK97 | AN20: Arunphat W. (Aiw) | AO20: PARTICLE BOARD | AP20: Normal | AW20: 0 | AX20: N | AZ20: CY-RTN : 02-03/10/2026 *VGM CUT OFF DD.05/10/2026 @ 12.00 REF : (VI(MDF) – 2026/274(Z) ** PLEASE CHECK OPEN GATE BEFORE RETURN CNTR ** | BA20: SI DD.18/9/26 | BB20: P | BC20: 2026-09-17 | BD20: 2026-10-02 | BE20: Y | BF20: PARTICLE BOARD | BG20: Line | BH20: S22 | BK20: LCH27 | BL20: 2026-10-02 | BP20: 2 | BY20: FULL | CC20: LCH05 | CF20: 0 Teu | CG20: CY/CY | CI20: wilaiporn@vanachai.com | CJ20: VANACHAI PANEL INDUSTRIES CO.,LTD. | CK20: TO THE ORDER OF INDUSTRIAL | CL20: SAMSAN INTERNATIONAL INC. | CN20: 202610051200 | CO20: 202610061500 | CQ20: S22-2301027 | CR20: BB0632 | CS20: VANACHAI GROUP PUBLIC COMPANY LIMITED | CT20: N | CW20: 2026-10-07 | CX20: 441114
A21: HASLS22260901608 | B21: 40Hx3 | C21: 3 | D21: 3 | F21: 0 | G21: 0 | H21: 0 | I21: 3 | J21: 6 | K21: N | L21: CHT | M21: SWDN | N21: 2610N | O21: THLCH | P21: LCH05 | Q21: IA | R21: 2026-10-08 | S21: KRINC | T21: INC03 | U21: KRINC | V21: 2026-10-16 | W21: KR | AA21: VANACHAI GROUP PUBLIC COMPANY LIMITED | AB21: VANACHAI PANEL INDUSTRIES CO., LTD. | AC21: 72996 | AD21: 84996 | AE21: OK | AH21: CHK | AI21: OK | AM21: TBKK97 | AN21: Arunphat W. (Aiw) | AO21: MEDIUM DENSITY FIBERBOARD | AP21: Normal | AW21: 0 | AX21: N | AZ21: CY 02/10/2026 - RTN 03/10/2026 (VI(MDF) – 2026/273(Z) ** PLEASE CHECK OPEN GATE BEFORE RETURN CNTR ** | BA21: SI DD.24/9/26 SI : 01/10 @15.00 | BB21: P | BC21: 2026-09-17 | BD21: 2026-09-30 | BE21: Y | BF21: PARTICLE BOARD | BG21: Line | BH21: S22 | BK21: LCH27 | BL21: 2026-10-02 | BP21: 3 | BY21: FULL | CC21: LCH05 | CF21: 0 Teu | CG21: CY/CY | CI21: wiranphat@vanachai.com | CJ21: VANACHAI PANEL INDUSTRIES CO.,LTD. | CK21: TO THE ORDER OF KOOKMIN BANK | CL21: NKG BOARD CO., LTD. | CN21: 202610051200 | CO21: 202610061500 | CQ21: S22-2301027 | CR21: BB0632 | CS21: VANACHAI GROUP PUBLIC COMPANY LIMITED | CT21: N | CW21: 2026-10-07
A22: HASLS22260902292 | B22: 40Hx3 | C22: 3 | D22: 3 | F22: 0 | G22: 0 | H22: 0 | I22: 3 | J22: 6 | K22: N | L22: CHT | M22: SWDN | N22: 2610N | O22: THLCH | P22: LCH05 | Q22: IA | R22: 2026-10-08 | S22: CNXMN | T22: XMN01 | U22: CNXMN | V22: 2026-10-13 | W22: IA | AA22: MASTERICH COMPANY LIMITED. | AB22: NATURAL RUBBER THREAD CO., LTD. | AC22: 78150 | AD22: 90150 | AE22: OK | AF22: SR | AH22: CHK | AI22: OK | AM22: TBKK19 | AN22: Kanokporn | AO22: RUBBER THREAD | AP22: Normal | AW22: 0 | AX22: N | AZ22: Pickup : 2026-09-30, Return : 2026-10-02 // EXTEND CLS TIME 02/10 @12.00 ** PLEASE CHECK OPEN GATE BEFORE RETURN CNTR ** | BA22: VOL 3 X 40'HC = G.W. 26,500.00/40'HCREQUEST : UP GRADE CONTAINER GOOD CLEAN NO SMELL CONTAINER | BB22: P | BC22: 2026-09-24 | BD22: 2026-10-01 | BE22: Y | BF22: RUBBER THREAD | BG22: Line | BH22: S22 | BK22: LCHY5 | BL22: 2026-09-30 | BP22: 3 | BY22: FULL | CA22: Y | CC22: LCH05 | CF22: 0 Teu | CG22: CY/CY | CI22: export@masterich.com | CJ22: NATURAL RUBBER THREAD CO.,LTD. | CK22: SHENZHEN QIANHAI ZHONGTAI YOULIAN | CL22: SHENZHEN QIANHAI ZHONGTAI YOULIAN | CN22: 202610051200 | CO22: 202610061500 | CQ22: S19-2210002 | CR22: BB0601 | CS22: MASTERICH COMPANY LIMITED. | CT22: N | CW22: 2026-10-03
A23: HASLS22260901600 | B23: 40Hx3 | C23: 3 | D23: 3 | F23: 0 | G23: 0 | H23: 0 | I23: 3 | J23: 6 | K23: N | L23: CHT | M23: SWDN | N23: 2610N | O23: THLCH | P23: LCH05 | Q23: IA | R23: 2026-10-08 | S23: KRINC | T23: INC03 | U23: KRINC | V23: 2026-10-16 | W23: KR | AA23: VANACHAI GROUP PUBLIC COMPANY LIMITED | AB23: VANACHAI GROUP PUBLIC COMPANY LIMITED | AC23: 72996 | AD23: 84996 | AE23: OK | AH23: CHK | AI23: OK | AM23: TBKK97 | AN23: Arunphat W. (Aiw) | AO23: MEDIUM DENSITY FIBER BOARDS | AP23: Normal | AW23: 0 | AX23: N | AZ23: CY 02/10/2026 - RTN 03/10/2026 (VI(MDF) – 2026/272(Z) ** PLEASE CHECK OPEN GATE BEFORE RETURN CNTR ** | BA23: SI DD.22/9/26 | BB23: P | BC23: 2026-09-17 | BD23: 2026-09-30 | BE23: Y | BF23: PARTICLE BOARD | BG23: Line | BH23: S22 | BK23: LCH27 | BL23: 2026-10-02 | BP23: 3 | BY23: FULL | CC23: LCH05 | CF23: 0 Teu | CG23: CY/CY | CI23: sompon@vanachai.com | CJ23: VANACHAI PANEL INDUSTRIES CO., LTD. | CK23: TO THE ORDER OF SHINHAN BANK SEOUL | CL23: DABINWOOD CO., LTD. | CN23: 202610051200 | CO23: 202610061500 | CQ23: S22-2301027 | CR23: BB0632 | CS23: VANACHAI GROUP PUBLIC COMPANY LIMITED | CT23: N | CW23: 2026-10-01 | CX23: 441114
A24: HASLS22260900917 | B24: R40Hx1 | C24: 1 | D24: 1 | F24: 0 | G24: 0 | H24: 0 | I24: 1 | J24: 2 | K24: N | L24: CHT | M24: SWDN | N24: 2610N | O24: THLCH | P24: LCH05 | Q24: IA | R24: 2026-10-08 | S24: HKHKG | T24: HKG03 | U24: HKHKG | V24: 2026-10-11 | W24: IA | AA24: DYNAMIC INTERTRANSPORT CO., LTD. | AB24: CP-MEIJI CO., LTD. | AC24: 21182.28 | AD24: 25182.28 | AE24: OK | AF24: SR | AH24: CHK | AI24: OK | AM24: TBKK55 | AN24: Vilaiporn | AO24: FRESH MILK AND MILK PRODUCT | AP24: Normal | AS24: RF// MIN:+0.0 MAX:+0.0 [COVER:CLOSE] | AT24: 45REx1 | AW24: 0 | AX24: N | AY24: OBL | AZ24: Pickup : 2026-10-02, Return : 2026-10-03 (Temp +0.0 / Vent Close) CLS TIME : 06/10/2026 @10.00 [1ST RTN 05/10 W/O ELECTRIC] | BA24: CY (BKK) , RT (LCB) , (Temp +0.0 / Vent Close) REQUEST : CLEAN AND GOOD CONTAINER FOR MILK PRODUCTSEND TO : nuttakan.des@cpintertrade.com,chuchat.ong@dynamic.co.th | BB24: P | BC24: 2026-09-10 | BD24: 2026-10-02 | BE24: Y | BF24: FRESH MILK AND MILK PRODUCT | BG24: Line | BH24: S22 | BK24: LCH27 | BL24: 2026-10-02 | BR24: 1 | BY24: FULL | CA24: Y | CC24: LCH05 | CF24: 0 Teu | CG24: CY/CY | CI24: nuttakan.des@cpintertrade.com;chuchat.ong@dynamic.co.th | CJ24: CP-MEIJI CO.,LTD. | CK24: CPF HONG KONG COMPANY LIMITED | CL24: CPF HONG KONG COMPANY LIMITED | CM24: CLOSED | CN24: 202610051200 | CO24: 202610061500 | CP24: 45RE x1: RF(Temp:+0.0' / Cover:CLOSE) | CQ24: S19-2308018 | CR24: BB0575 | CS24: DYNAMIC INTERTRANSPORT CO., LTD. | CT24: N | CW24: 2026-10-07
A25: HASLS22260801601 | B25: R40Hx1 | C25: 1 | D25: 1 | F25: 0 | G25: 0 | H25: 0 | I25: 1 | J25: 2 | K25: N | L25: CHT | M25: SWDN | N25: 2610N | O25: THLCH | P25: LCH05 | Q25: IA | R25: 2026-10-08 | S25: HKHKG | T25: HKG03 | U25: HKHKG | V25: 2026-10-11 | W25: IA | AA25: DYNAMIC INTERTRANSPORT CO., LTD. | AB25: CP-MEIJI CO., LTD. | AC25: 23084.88 | AD25: 27084.88 | AE25: OK | AF25: SR | AH25: CHK | AI25: OK | AM25: TBKK55 | AN25: Vilaiporn | AO25: FRESH MILK AND MILK PRODUCT | AP25: Normal | AS25: RF// MIN:+0.0 MAX:+0.0 [COVER:CLOSE] | AT25: 45REx1 | AW25: 0 | AX25: N | AY25: OBL | AZ25: Pickup : 2026-10-02, Return : 2026-10-03 RF45REx1 (Temp +0.0 / Vent Close) CLS TIME : 06/10/2026 @10.00 [1ST RTN 05/10 W/O ELECTRIC] | BA25: FM TSNA 2609N SKIP THAILAND 25/08 FM KJT 2610N DD 16/09 CY (BKK) , RT (LCB) , (Temp +0.0 / Vent Close) REQUEST : CLEAN AND GOOD CONTAINER FOR MILK PRODUCTSEND TO : nuttakan.des@cpintertrade.com,chuchat.ong@dynamic.co.th | BB25: P | BC25: 2026-08-19 | BD25: 2026-10-02 | BE25: Y | BF25: FRESH MILK AND MILK PRODUCT | BG25: Line | BH25: S22 | BK25: LCH27 | BL25: 2026-10-02 | BR25: 1 | BY25: FULL | CA25: Y | CC25: LCH05 | CF25: 0 Teu | CG25: CY/CY | CI25: nuttakan.des@cpintertrade.com;chuchat.ong@dynamic.co.th | CJ25: CP-MEIJI CO.,LTD. | CK25: CPF HONG KONG COMPANY LIMITED | CL25: CPF HONG KONG COMPANY LIMITED | CM25: CLOSED | CN25: 202610051200 | CO25: 202610061500 | CP25: 45RE x1: RF(Temp:+0.0' / Cover:CLOSE) | CQ25: S19-2308018 | CR25: BB0575 | CS25: DYNAMIC INTERTRANSPORT CO., LTD. | CT25: N | CW25: 2026-10-07
A26: HASLS22260902204 | B26: R40Hx1 | C26: 1 | D26: 1 | F26: 0 | G26: 0 | H26: 0 | I26: 1 | J26: 2 | K26: N | L26: CHT | M26: SWDN | N26: 2610N | O26: THLCH | P26: LCH05 | Q26: IA | R26: 2026-10-08 | S26: HKHKG | T26: HKG03 | U26: HKHKG | V26: 2026-10-11 | W26: IA | AA26: STAR SHIPPING CARGO LIKES CO., LTD. | AB26: AN NAM DRAGON 2017 CO., LTD. | AC26: 22194.3 | AD26: 26194.3 | AE26: OK | AH26: CHK | AM26: TBKK97 | AN26: Arunphat W. (Aiw) | AO26: FRESH FRUITS, VEGETABLES, FOODSTUFF | AP26: Normal | AS26: RF// MIN:+4.0 MAX:+4.0 [COVER:OPEN] | AT26: 45REx1 | AW26: 0 | AX26: N | AZ26: Pickup : 2026-10-05, Return : 2026-10-06 (Temp +4.0℃ / Vent 15% Open) CLS TIME 07/10 @12.00 [1ST RTN 06/10 W/O ELCTRIC] | BA26: FM SWAT 2610N DD 03/10 | BB26: P | BC26: 2026-09-23 | BD26: 2026-10-06 | BE26: Y | BF26: FRESH FRUITS, VEGETABLES, FOODSTUFF | BG26: Line | BH26: S22 | BK26: LCH27 | BL26: 2026-10-05 | BR26: 1 | BY26: FULL | CA26: Y | CC26: LCH05 | CF26: 0 Teu | CG26: CY/CY | CI26: STARSHIPPING.IM@GMAIL.COM | CJ26: AN NAM DRAGON 2017 CO.,LTD. | CK26: XIN THAI XIANG IMPORTS AND EXPORTS | CL26: XIN THAI XIANG IMPORTS AND EXPORTS | CN26: 202610051200 | CO26: 202610061500 | CP26: 45RE x1: RF(Temp:+4.0' / Cover:FULL OPEN) | CQ26: S22-2401023 | CR26: THTQZX | CS26: STAR SHIPPING CARGO LIKES CO., LTD. | CT26: N | CW26: 2026-10-08
A27: HASLS22260900918 | B27: R40Hx1 | C27: 1 | D27: 1 | F27: 0 | G27: 0 | H27: 0 | I27: 1 | J27: 2 | K27: N | L27: CHT | M27: SWDN | N27: 2610N | O27: THLCH | P27: LCH05 | Q27: IA | R27: 2026-10-08 | S27: HKHKG | T27: HKG03 | U27: HKHKG | V27: 2026-10-11 | W27: IA | AA27: DYNAMIC INTERTRANSPORT CO., LTD. | AB27: CP-MEIJI CO., LTD. | AC27: 23655.66 | AD27: 27655.66 | AE27: OK | AF27: SR | AH27: CHK | AI27: OK | AM27: TBKK55 | AN27: Vilaiporn | AO27: FRESH MILK AND MILK PRODUCT | AP27: Normal | AS27: RF// MIN:+0.0 MAX:+0.0 [COVER:CLOSE] | AT27: 45REx1 | AW27: 0 | AX27: N | AY27: OBL | AZ27: Pickup : 2026-10-02, Return : 2026-10-03 (Temp +0.0 / Vent Close) CLS TIME : 06/10/2026 @10.00 [1ST RTN 05/10 W/O ELECTRIC] | BA27: CY (BKK) , RT (LCB) , (Temp +0.0 / Vent Close) REQUEST : CLEAN AND GOOD CONTAINER FOR MILK PRODUCTSEND TO : nuttakan.des@cpintertrade.com,chuchat.ong@dynamic.co.th | BB27: P | BC27: 2026-09-10 | BD27: 2026-10-02 | BE27: Y | BF27: FRESH MILK AND MILK PRODUCT | BG27: Line | BH27: S22 | BK27: LCH27 | BL27: 2026-10-02 | BR27: 1 | BY27: FULL | CA27: Y | CC27: LCH05 | CF27: 0 Teu | CG27: CY/CY | CI27: nuttakan.des@cpintertrade.com;chuchat.ong@dynamic.co.th | CJ27: CP-MEIJI CO.,LTD. | CK27: CPF HONG KONG COMPANY LIMITED | CL27: CPF HONG KONG COMPANY LIMITED | CM27: CLOSED | CN27: 202610051200 | CO27: 202610061500 | CP27: 45RE x1: RF(Temp:+0.0' / Cover:CLOSE) | CQ27: S19-2308018 | CR27: BB0575 | CS27: DYNAMIC INTERTRANSPORT CO., LTD. | CT27: N | CW27: 2026-10-07
A28: TOTAL | B28: 2 | F28: 0 | G28: 28 | H28: 0 | I28: 21 | J28: 70 | AC28: 879398.77 | AD28: 1028598.8 | BM28: 0 | BN28: 25 | BO28: 0 | BP28: 17 | BQ28: 1 | BR28: 4 | BS28: 0 | BT28: 0 | BU28: 0 | BV28: 0 | BW28: 2 | BX28: 0
A29: COC | B29: 5 | F29: 0 | G29: 26 | H29: 0 | I29: 21 | J29: 68
A30: SOC | B30: 0 | F30: 0 | G30: 2 | H30: 0 | I30: 0 | J30: 2
A31: 26 | B31: 49

Sheet 3.GateMove
A1: Container No | B1: Location | C1: Move | D1: GateDate | E1: GateTime | F1: BL No | G1: Shipper | H1: TPSZ | I1: Remark | J1: EmpName | K1: CND | L1: F/E | M1: BK No | N1: BK QTY | O1: Built Year | P1: RF Brand | Q1: RF Model | R1: Vessel | S1: Voyage | T1: LWHARF | U1: POL | V1: POL Date | W1: POD | X1: POD Date | Y1: SOC | Z1: Seal No | AA1: Truck No | AB1: Haulier | AC1: Driver Tel | AD1: InpDate | AE1: InpTime | AF1: EmpNo | AG1: SendId | AH1: SendDate | AI1: Cnee Code | AJ1: Cnee Name | AK1: Weight
A2: BEAU2356127 | B2: LCH05 | C2: IFV | D2: 2026-10-01 | E2: 0335 | F2: HASLS22260901146 | G2: WHA GC LOGISTICS COMPANY LIMITED | H2: 22GP | I2: EMAIL | J2: EDI2 | L2: Full | M2: HASLS22260901146 | N2: 20'x4 | O2: 2014 | R2: SWDN | S2: 2610N | T2: LCH05 | U2: THLCH | V2: 2026-10-08 | W2: CNXMN | X2: 2026-10-13 | AD2: 2026-10-01 | AE2: 0801 | AF2: EDI2 | AJ2: SINOCHEM PETROCHEMICAL
A3: BEAU2477638 | B3: LCH05 | C3: IFV | D3: 2026-10-04 | E3: 1438 | F3: HASLS22260901029 | G3: THAI POLYCARBONATE CO., LTD. | H3: 22GP | I3: EMAIL | J3: EDI2 | L3: Full | M3: HASLS22260901029 | N3: 20'x3 | O3: 2015 | R3: SWDN | S3: 2610N | T3: LCH05 | U3: THLCH | V3: 2026-10-08 | W3: CNXMN | X3: 2026-10-13 | AD3: 2026-10-04 | AE3: 2002 | AF3: EDI2 | AJ3: PLASTEL INDUSTRIES CO.,LTD.
A4: BEAU2985449 | B4: LCH05 | C4: IFV | D4: 2026-10-02 | E4: 2022 | F4: HASLS22260901873 | G4: DIMERCO EXPRESS (THAILAND) CO., LTD. | H4: 22GP | I4: EMAIL | J4: EDI2 | L4: Full | M4: HASLS22260901873 | N4: 20'x1 | O4: 2017 | R4: SWDN | S4: 2610N | T4: LCH05 | U4: THLCH | V4: 2026-10-08 | W4: CNXMN | X4: 2026-10-13 | AD4: 2026-10-03 | AE4: 0201 | AF4: EDI2 | AJ4: DIVERSIFIED INTERNATIONAL
A5: FBIU5092414 | B5: LCH05 | C5: IFV | D5: 2026-10-06 | E5: 1850 | F5: HASLS22260902204 | G5: STAR SHIPPING CARGO LIKES CO., LTD. | H5: 45RE | I5: EMAIL | J5: EDI2 | L5: Full | M5: HASLS22260902204 | N5: R40Hx1 | O5: 2021 | P5: CARRIER | Q5: Primeline | R5: SWDN | S5: 2610N | T5: LCH05 | U5: THLCH | V5: 2026-10-08 | W5: HKHKG | X5: 2026-10-11 | AD5: 2026-10-07 | AE5: 0201 | AF5: EDI2 | AJ5: XIN THAI XIANG IMPORTS AND EXPORTS
A6: FBIU5103210 | B6: LCH05 | C6: IFV | D6: 2026-10-03 | E6: 0652 | F6: HASLS22260801601 | G6: DYNAMIC INTERTRANSPORT CO., LTD. | H6: 45RE | I6: EMAIL | J6: EDI2 | L6: Full | M6: HASLS22260801601 | N6: R40Hx1 | O6: 2021 | P6: CARRIER | Q6: 69NT40-561-503 | R6: SWDN | S6: 2610N | T6: LCH05 | U6: THLCH | V6: 2026-10-08 | W6: HKHKG | X6: 2026-10-11 | AD6: 2026-10-03 | AE6: 1401 | AF6: EDI2 | AJ6: CPF HONG KONG COMPANY LIMITED
A7: FBIU5103313 | B7: LCH05 | C7: IFV | D7: 2026-10-03 | E7: 0725 | F7: HASLS22260900917 | G7: DYNAMIC INTERTRANSPORT CO., LTD. | H7: 45RE | I7: EMAIL | J7: EDI2 | L7: Full | M7: HASLS22260900917 | N7: R40Hx1 | O7: 2021 | P7: CARRIER | Q7: 69NT40-561-503 | R7: SWDN | S7: 2610N | T7: LCH05 | U7: THLCH | V7: 2026-10-08 | W7: HKHKG | X7: 2026-10-11 | AD7: 2026-10-03 | AE7: 1401 | AF7: EDI2 | AJ7: CPF HONG KONG COMPANY LIMITED
A8: FSCU5893590 | B8: LCH05 | C8: IFV | D8: 2026-10-03 | E8: 0727 | F8: HASLS22260900918 | G8: DYNAMIC INTERTRANSPORT CO., LTD. | H8: 45RE | I8: EMAIL | J8: EDI2 | L8: Full | M8: HASLS22260900918 | N8: R40Hx1 | O8: 2020 | P8: CARRIER | Q8: 69NT40-561-500 | R8: SWDN | S8: 2610N | T8: LCH05 | U8: THLCH | V8: 2026-10-08 | W8: HKHKG | X8: 2026-10-11 | AD8: 2026-10-03 | AE8: 1401 | AF8: EDI2 | AJ8: CPF HONG KONG COMPANY LIMITED
A9: GCXU2429912 | B9: LCH05 | C9: IFV | D9: 2026-10-01 | E9: 2219 | F9: HASLS22260800649 | G9: NIPPON EXPRESS LOGISTICS (THAILAND) CO., LTD. | H9: 22GP | I9: EMAIL | J9: EDI2 | L9: Full | M9: HASLS22260800649 | N9: 20'x1 | O9: 2024 | R9: SWDN | S9: 2610N | T9: LCH05 | U9: THLCH | V9: 2026-10-08 | W9: HKHKG | X9: 2026-10-11 | AD9: 2026-10-02 | AE9: 0201 | AF9: EDI2 | AJ9: NIPPON EXPRESS (H.K.) CO.,LTD.
A10: HALU2083638 | B10: LCH05 | C10: IFV | D10: 2026-09-26 | E10: 0524 | F10: HASLS22260901415 | G10: SCGJWD LOGISTICS PUBLIC COMPANY LIMITED | H10: 22GP | I10: EMAIL | J10: EDI2 | L10: Full | M10: HASLS22260901415 | N10: 20'x1 | O10: 2015 | R10: KMGY | S10: 2610N | T10: LCH05 | U10: THLCH | V10: 2026-10-08 | W10: CNXMN | X10: 2026-10-13 | AD10: 2026-09-26 | AE10: 0801 | AF10: EDI2 | AJ10: SHANGHAI JIUCHENG TRADE CO., LTD.
A11: HALU2313129 | B11: LCH05 | C11: IFV | D11: 2026-10-03 | E11: 0101 | F11: HASLS22260900563 | G11: WHA GC LOGISTICS COMPANY LIMITED | H11: 22GP | I11: EMAIL | J11: EDI2 | L11: Full | M11: HASLS22260900563 | N11: 20'x8 | O11: 2023 | R11: SWDN | S11: 2610N | T11: LCH05 | U11: THLCH | V11: 2026-10-08 | W11: HKHKG | X11: 2026-10-11 | AD11: 2026-10-03 | AE11: 0801 | AF11: EDI2 | AJ11: GC MARKETING SOLUTIONS (SHANGHAI)
A12: HALU2352969 | B12: LCH05 | C12: IFV | D12: 2026-10-01 | E12: 0335 | F12: HASLS22260901146 | G12: WHA GC LOGISTICS COMPANY LIMITED | H12: 22GP | I12: EMAIL | J12: EDI2 | L12: Full | M12: HASLS22260901146 | N12: 20'x4 | O12: 2023 | R12: SWDN | S12: 2610N | T12: LCH05 | U12: THLCH | V12: 2026-10-08 | W12: CNXMN | X12: 2026-10-13 | AD12: 2026-10-01 | AE12: 0801 | AF12: EDI2 | AJ12: SINOCHEM PETROCHEMICAL
A13: HALU2400286 | B13: LCH05 | C13: IFV | D13: 2026-10-05 | E13: 0928 | F13: HASLS22260900563 | G13: WHA GC LOGISTICS COMPANY LIMITED | H13: 22GP | I13: EMAIL | J13: EDI2 | L13: Full | M13: HASLS22260900563 | N13: 20'x8 | O13: 2024 | R13: SWDN | S13: 2610N | T13: LCH05 | U13: THLCH | V13: 2026-10-08 | W13: HKHKG | X13: 2026-10-11 | AD13: 2026-10-05 | AE13: 1402 | AF13: EDI2 | AJ13: GC MARKETING SOLUTIONS (SHANGHAI)
A14: HALU2446630 | B14: LCH05 | C14: IFV | D14: 2026-10-03 | E14: 1413 | F14: HASLS22260900777 | G14: T.C.PHARMACEUTICAL INDUSTRIES CO., LTD. | H14: 22GP | I14: EMAIL | J14: EDI2 | L14: Full | M14: HASLS22260900777 | N14: 20'x1 | O14: 2024 | R14: SWDN | S14: 2610N | T14: LCH05 | U14: THLCH | V14: 2026-10-08 | W14: KRINC | X14: 2026-10-16 | AD14: 2026-10-03 | AE14: 2002 | AF14: EDI2 | AJ14: WORL-KET COMPANY LIMITED
A15: HALU2453943 | B15: LCH05 | C15: IFV | D15: 2026-10-05 | E15: 0832 | F15: HASLS22260900563 | G15: WHA GC LOGISTICS COMPANY LIMITED | H15: 22GP | I15: EMAIL | J15: EDI2 | L15: Full | M15: HASLS22260900563 | N15: 20'x8 | O15: 2024 | R15: SWDN | S15: 2610N | T15: LCH05 | U15: THLCH | V15: 2026-10-08 | W15: HKHKG | X15: 2026-10-11 | AD15: 2026-10-05 | AE15: 1402 | AF15: EDI2 | AJ15: GC MARKETING SOLUTIONS (SHANGHAI)
A16: HALU2526124 | B16: LCH05 | C16: IFV | D16: 2026-10-03 | E16: 0101 | F16: HASLS22260900563 | G16: WHA GC LOGISTICS COMPANY LIMITED | H16: 22GP | I16: EMAIL | J16: EDI2 | L16: Full | M16: HASLS22260900563 | N16: 20'x8 | O16: 2025 | R16: SWDN | S16: 2610N | T16: LCH05 | U16: THLCH | V16: 2026-10-08 | W16: HKHKG | X16: 2026-10-11 | AD16: 2026-10-03 | AE16: 0801 | AF16: EDI2 | AJ16: GC MARKETING SOLUTIONS (SHANGHAI)
A17: HALU2567648 | B17: LCH05 | C17: IFV | D17: 2026-10-03 | E17: 2004 | F17: HASLS22260900563 | G17: WHA GC LOGISTICS COMPANY LIMITED | H17: 22GP | I17: EMAIL | J17: EDI2 | L17: Full | M17: HASLS22260900563 | N17: 20'x8 | O17: 2025 | R17: SWDN | S17: 2610N | T17: LCH05 | U17: THLCH | V17: 2026-10-08 | W17: HKHKG | X17: 2026-10-11 | AD17: 2026-10-04 | AE17: 0201 | AF17: EDI2 | AJ17: GC MARKETING SOLUTIONS (SHANGHAI)
A18: HALU2568731 | B18: LCH05 | C18: IFV | D18: 2026-10-03 | E18: 2004 | F18: HASLS22260900563 | G18: WHA GC LOGISTICS COMPANY LIMITED | H18: 22GP | I18: EMAIL | J18: EDI2 | L18: Full | M18: HASLS22260900563 | N18: 20'x8 | O18: 2025 | R18: SWDN | S18: 2610N | T18: LCH05 | U18: THLCH | V18: 2026-10-08 | W18: HKHKG | X18: 2026-10-11 | AD18: 2026-10-04 | AE18: 0201 | AF18: EDI2 | AJ18: GC MARKETING SOLUTIONS (SHANGHAI)
A19: HLHU6407690 | B19: LCH05 | C19: IFV | D19: 2026-10-03 | E19: 1131 | F19: HASLS22260901600 | G19: VANACHAI GROUP PUBLIC COMPANY LIMITED | H19: 45GP | I19: EMAIL | J19: EDI2 | L19: Full | M19: HASLS22260901600 | N19: 40Hx3 | O19: 2024 | R19: SWDN | S19: 2610N | T19: LCH05 | U19: THLCH | V19: 2026-10-08 | W19: KRINC | X19: 2026-10-16 | AD19: 2026-10-03 | AE19: 2002 | AF19: EDI2 | AJ19: TO THE ORDER OF SHINHAN BANK SEOUL
A20: HLHU8108620 | B20: LCH05 | C20: IFV | D20: 2026-10-03 | E20: 1218 | F20: HASLS22260901610 | G20: VANACHAI GROUP PUBLIC COMPANY LIMITED | H20: 45GP | I20: EMAIL | J20: EDI2 | L20: Full | M20: HASLS22260901610 | N20: 40Hx2 | O20: 2021 | R20: SWDN | S20: 2610N | T20: LCH05 | U20: THLCH | V20: 2026-10-08 | W20: KRINC | X20: 2026-10-16 | AD20: 2026-10-03 | AE20: 2002 | AF20: EDI2 | AJ20: TO THE ORDER OF INDUSTRIAL
... A47: SKLU3510078 | B47: LCH05 | C47: IFV | D47: 2026-10-01 | E47: 0345 | F47: HASLS22260901146 | G47: WHA GC LOGISTICS COMPANY LIMITED | H47: 22GP | I47: EMAIL | J47: EDI2 | L47: Full | M47: HASLS22260901146 | N47: 20'x4 | O47: 2015 | R47: SWDN | S47: 2610N | T47: LCH05 | U47: THLCH | V47: 2026-10-08 | W47: CNXMN | X47: 2026-10-13 | AD47: 2026-10-01 | AE47: 0801 | AF47: EDI2 | AJ47: SINOCHEM PETROCHEMICAL
A48: SKRU1900119 | B48: LCH05 | C48: IFV | D48: 2026-10-05 | E48: 1414 | F48: HASLS22260900990 | G48: NAMYONG LOGISTICS CO., LTD. | H48: 22RE | I48: EMAIL | J48: EDI2 | L48: Full | M48: HASLS22260900990 | N48: 20RFx1 | O48: 2019 | P48: CARRIER | Q48: PRIME LINE | R48: SWDN | S48: 2610N | T48: LCH05 | U48: THLCH | V48: 2026-10-08 | W48: HKHKG | X48: 2026-10-11 | AD48: 2026-10-05 | AE48: 2001 | AF48: EDI2 | AJ48: FULLY WIN CORPORATION LIMITED
A49: SKRU1900119
A50: BEAU2356127
A51: BEAU2477638
A52: BEAU2985449
A53: FBIU5092414
A54: FBIU5103210
A55: FBIU5103313
A56: FSCU5893590
A57: GCXU2429912
A58: HALU2083638
A59: HALU2313129
A60: HALU2352969
... A95: SKLU3510078

Sheet CS
A1: copyเบอร์ตู้มาวาง | R1: เปลี่ยนวันที่ตามปฎิทิน | W1: เช็ควันคืนตู้ | AA1: =SUM(AA3:AA1353) -> 3000 | AG1: =SUM(AG3:AG1353) -> 0 | AH1: =SUM(AH3:AH1353) -> 0 | AI1: =SUM(AI3:AI1353) -> 3000
A2: Container No. | B2: Group | C2: Location | D2: Booking No. | E2: Shipper | F2: Org Shipper | G2: RCVCD | H2: POL | I2: POD | J2: TS PORT | K2: Type Size | L2: CGO TERM | M2: DG | N2: RF | O2: Vessel | P2: Voyage | Q2: SVC | R2: Size | S2: Original Schedule | T2: ETD | U2: Vssl Delay | V2: 1st Date allow to return | W2: Date In | X2: Total Stay | Y2: Normal F/T Terminal | Z2: Total Storage Days | AA2: Total Storage Charge | AB2: Special F/T | AC2: HQ Ref No. / TML / APP BY | AD2: Free Time Customer | AE2: คืนก่อนเรือออก | AF2: Over F/T Customer | AG2: Amount due to Customer | AH2: Collection | AI2: Amount due to HAL | AJ2: Remark | AK2: SALESNM | AL2: CUST ETD | AM2: PICK UP | AN2: COMMOM REMAKRS | AO2: ROLL
A3: BEAU2356127 | B3: =IF(C3=Charge!$M$1,Charge!$J$1,IF(C3=Charge!$M$23,Charge!$J$23,IF(C3=Charge!$M$17,Charge!$J$17,IF(C3=Charge!$N$17,Charge!$J$17,Charge!$J$7)))) -> G2 | C3: =VLOOKUP(A3,'1.Loading'!A:R,14,FALSE) -> LCH05 | D3: =VLOOKUP(A3,'1.Loading'!A:R,17,FALSE) -> HASLS22260901146 | E3: =VLOOKUP(D3,'2.Bookinglist'!A:CT,27,FALSE) -> WHA GC LOGISTICS COMPANY LIMITED | F3: =VLOOKUP(D3,'2.Bookinglist'!A:CT,28,FALSE) -> PTT GLOBAL CHEMICAL PUBLIC COMPANY LIMITED | G3: =VLOOKUP(D3,'2.Bookinglist'!A:E,5,FALSE) -> 0 | H3: =VLOOKUP(D3,'2.Bookinglist'!A:CT,15,FALSE) -> THLCH | I3: =VLOOKUP(D3,'2.Bookinglist'!A:CT,19,FALSE) -> CNXMN | J3: =VLOOKUP(D3,'2.Bookinglist'!A:CT,26,FALSE) -> 0 | K3: =VLOOKUP(A3,'1.Loading'!A:R,5,FALSE) -> 22GP | L3: =VLOOKUP(D3,'2.Bookinglist'!A:CT,85,FALSE) -> CY/CY | M3: =IF(VLOOKUP(D3,'2.Bookinglist'!A:CT,43,FALSE)=0,"","DG") | N3: =IF(RIGHT(K3,2)="RE","RF","") | O3: =VLOOKUP(A3,'1.Loading'!A:R,3,FALSE) -> SWDN | P3: =VLOOKUP(A3,'1.Loading'!A:R,4,FALSE) -> 2610N | Q3: =VLOOKUP(D3,'2.Bookinglist'!A:CT,12,FALSE) -> CHT | R3: =IF(LEFT(K3,2)="22","20'","40'") -> 20' | T3: =VLOOKUP(A3,'1.Loading'!A:R,2,FALSE) -> 2026-10-08 | U3: =T3-S3 -> 46303 | W3: =VLOOKUP(A3,'3.GateMove'!A:D,4,FALSE) -> 2026-10-01 | X3: =((T3-W3)+1) -> 8 | Y3: =IF(AND(OR(C3="BKK01",C3="BKK04"),L3="CFS/CY"),0,IF(M3="DG",1,IF(LEFT(C3,3)="LCH",7,IF(C3="BKK02",5,3)))) -> 7 | Z3: =IF(IF(AND(AC3="TML",AB3>0),((T3-W3)+1)-AB3,((T3-W3)+1)-Y3)>0,IF(AND(AC3="TML",AB3>0),((T3-W3)+1)-AB3,((T3-W3)+1)-Y3),0) -> 1 | AA3: =IF(AND(B3="G1",M3=""),IF(R3="20'", VLOOKUP(Z3,Charge!$K$2:$M$5,2,TRUE)+(Z3-VLOOKUP(Z3,Charge!$K$2:$M$5,1,TRUE))*VLOOKUP(Z3,Charge!$K$2:$M$5,3,TRUE), VLOOKUP(Z3,Charge!$N$2:$P$5,2,TRUE)+(Z3-VLOOKUP(Z3,Charge!$N$2:$P$5,1,TRUE))*VLOOKUP(Z3,Charge!$N$2:$P$5,3,TRUE)), IF(AND(B3="G1",M3="DG"),IF(R3="20'", VLOOKUP(Z3,Charge!$R$2:$T$5,2,TRUE)+(Z3-VLOOKUP(Z3,Charge!$R$2:$T$5,1,TRUE))*VLOOKUP(Z3,Charge!$R$2:$T$5,3,TRUE), VLOOKUP(Z3,Charge!$U$2:$W$5,2,TRUE)+(Z3-VLOOKUP(Z3,Charge!$U$2:$W$5,1,TRUE))*VLOOKUP(Z3,Charge!$U$2:$W$5,3,TRUE)), IF(AND(B3="G3",M3=""),IF(R3="20'", VLOOKUP(Z3,Charge!$K$18:$M$21,2,TRUE)+(Z3-VLOOKUP(Z3,Charge!$K$18:$M$21,1,TRUE))*VLOOKUP(Z3,Charge!$K$18:$M$21,3,TRUE), VLOOKUP(Z3,Charge!$N$18:$P$21,2,TRUE)+(Z3-VLOOKUP(Z3,Charge!$N$18:$P$21,1,TRUE))*VLOOKUP(Z3,Charge!$N$18:$P$21,3,TRUE)), IF(AND(B3="G3",M3="DG"),IF(R3="20'", VLOOKUP(Z3,Charge!$R$18:$T$21,2,TRUE)+(Z3-VLOOKUP(Z3,Charge!$R$18:$T$21,1,TRUE))*VLOOKUP(Z3,Charge!$R$18:$T$21,3,TRUE), VLOOKUP(Z3,Charge!$U$18:$W$21,2,TRUE)+(Z3-VLOOKUP(Z3,Charge!$U$18:$W$21,1,TRUE))*VLOOKUP(Z3,Charge!$U$18:$W$21,3,TRUE)), IF(AND(B3="G2",M3=""),IF(R3="20'", VLOOKUP(Z3,Charge!$K$9:$M$12,2,TRUE)+(Z3-VLOOKUP(Z3,Charge!$K$9:$M$12,1,TRUE))*VLOOKUP(Z3,Charge!$K$9:$M$12,3,TRUE), VLOOKUP(Z3,Charge!$N$9:$P$12,2,TRUE)+(Z3-VLOOKUP(Z3,Charge!$N$9:$P$12,1,TRUE))*VLOOKUP(Z3,Charge!$N$9:$P$12,3,TRUE)), IF(AND(B3="G2",M3="DG"),IF(R3="20'", VLOOKUP(Z3,Charge!$R$9:$T$12,2,TRUE)+(Z3-VLOOKUP(Z3,Charge!$R$9:$T$12,1,TRUE))*VLOOKUP(Z3,Charge!$R$9:$T$12,3,TRUE), VLOOKUP(Z3,Charge!$U$9:$W$12,2,TRUE)+(Z3-VLOOKUP(Z3,Charge!$U$9:$W$12,1,TRUE))*VLOOKUP(Z3,Charge!$U$9:$W$12,3,TRUE)),IF(AND(B3="G4",M3=""),IF(R3="20'",Z3*Charge!$M$25,Z3*Charge!$P$25),IF(AND(B3="G4",M3="DG"),IF(R3="20'",Z3*Charge!$T$25,Z3*Charge!$W$25),0)))))))) -> 125 | AD3: =IF(M3="DG",3,IF(N3="RF",3,5))+IF(AND(LEFT(C3,3)="BKK",N3="RF",Q3="KTS"),1,0)+IF(Q3="KHS",1,0) -> 5 | AE3: =(T3-V3)+1 -> 46304 | AF3: =IF(AB3>IF((V3-W3)>0,V3-W3,0),0,IF(AB3<IF((V3-W3)>0,V3-W3,0),IF((V3-W3)>0,V3-W3,0)-AB3,IF((V3-W3)>0,V3-W3,0))) -> 0 | AG3: =IF(AND(M3=""),IF(R3="20'", VLOOKUP(AF3,Charge!$K$31:$M$34,2,TRUE)+(AF3-VLOOKUP(AF3,Charge!$K$31:$M$34,1,TRUE))*VLOOKUP(AF3,Charge!$K$31:$M$34,3,TRUE), VLOOKUP(AF3,Charge!$N$31:$P$34,2,TRUE)+(AF3-VLOOKUP(AF3,Charge!$N$31:$P$34,1,TRUE))*VLOOKUP(AF3,Charge!$N$31:$P$34,3,TRUE)), IF(AND(M3="DG"),IF(R3="20'", VLOOKUP(AF3,Charge!$R$31:$T$34,2,TRUE)+(AF3-VLOOKUP(AF3,Charge!$R$31:$T$34,1,TRUE))*VLOOKUP(AF3,Charge!$R$31:$T$34,3,TRUE), VLOOKUP(AF3,Charge!$U$31:$W$34,2,TRUE)+(AF3-VLOOKUP(AF3,Charge!$U$31:$W$34,1,TRUE))*VLOOKUP(AF3,Charge!$U$31:$W$34,3,TRUE)),0)) -> 0 | AI3: =AA3-AH3 -> 125 | AK3: =VLOOKUP(D3,'2.Bookinglist'!A:CT,40,FALSE) -> Dharaporn | AL3: =VLOOKUP(D3,'2.Bookinglist'!A:CW,101,FALSE) -> 2026-10-01 | AM3: =VLOOKUP(D3,'2.Bookinglist'!A:BK,63,FALSE) -> LCHY5 | AN3: =VLOOKUP(D3,'2.Bookinglist'!A:AZ,52,FALSE) -> CY-RTN 21-25/09/26 *PR2610003144* | AO3: =VLOOKUP(D3,'2.Bookinglist'!A:CY,103,FALSE) -> 0
A4: BEAU2477638 | B4: =IF(C4=Charge!$M$1,Charge!$J$1,IF(C4=Charge!$M$23,Charge!$J$23,IF(C4=Charge!$M$17,Charge!$J$17,IF(C4=Charge!$N$17,Charge!$J$17,Charge!$J$7)))) -> G2 | C4: =VLOOKUP(A4,'1.Loading'!A:R,14,FALSE) -> LCH05 | D4: =VLOOKUP(A4,'1.Loading'!A:R,17,FALSE) -> HASLS22260901029 | E4: =VLOOKUP(D4,'2.Bookinglist'!A:CT,27,FALSE) -> THAI POLYCARBONATE CO., LTD. | F4: =VLOOKUP(D4,'2.Bookinglist'!A:CT,28,FALSE) -> THAI POLYCARBONATE CO., LTD. | G4: =VLOOKUP(D4,'2.Bookinglist'!A:E,5,FALSE) -> 0 | H4: =VLOOKUP(D4,'2.Bookinglist'!A:CT,15,FALSE) -> THLCH | I4: =VLOOKUP(D4,'2.Bookinglist'!A:CT,19,FALSE) -> CNXMN | J4: =VLOOKUP(D4,'2.Bookinglist'!A:CT,26,FALSE) -> 0 | K4: =VLOOKUP(A4,'1.Loading'!A:R,5,FALSE) -> 22GP | L4: =VLOOKUP(D4,'2.Bookinglist'!A:CT,85,FALSE) -> CY/CY | M4: =IF(VLOOKUP(D4,'2.Bookinglist'!A:CT,43,FALSE)=0,"","DG") | N4: =IF(RIGHT(K4,2)="RE","RF","") | O4: =VLOOKUP(A4,'1.Loading'!A:R,3,FALSE) -> SWDN | P4: =VLOOKUP(A4,'1.Loading'!A:R,4,FALSE) -> 2610N | Q4: =VLOOKUP(D4,'2.Bookinglist'!A:CT,12,FALSE) -> CHT | R4: =IF(LEFT(K4,2)="22","20'","40'") -> 20' | T4: =VLOOKUP(A4,'1.Loading'!A:R,2,FALSE) -> 2026-10-08 | U4: =T4-S4 -> 46303 | W4: =VLOOKUP(A4,'3.GateMove'!A:D,4,FALSE) -> 2026-10-04 | X4: =((T4-W4)+1) -> 5 | Y4: =IF(AND(OR(C4="BKK01",C4="BKK04"),L4="CFS/CY"),0,IF(M4="DG",1,IF(LEFT(C4,3)="LCH",7,IF(C4="BKK02",5,3)))) -> 7 | Z4: =IF(IF(AND(AC4="TML",AB4>0),((T4-W4)+1)-AB4,((T4-W4)+1)-Y4)>0,IF(AND(AC4="TML",AB4>0),((T4-W4)+1)-AB4,((T4-W4)+1)-Y4),0) -> 0 | AA4: =IF(AND(B4="G1",M4=""),IF(R4="20'", VLOOKUP(Z4,Charge!$K$2:$M$5,2,TRUE)+(Z4-VLOOKUP(Z4,Charge!$K$2:$M$5,1,TRUE))*VLOOKUP(Z4,Charge!$K$2:$M$5,3,TRUE), VLOOKUP(Z4,Charge!$N$2:$P$5,2,TRUE)+(Z4-VLOOKUP(Z4,Charge!$N$2:$P$5,1,TRUE))*VLOOKUP(Z4,Charge!$N$2:$P$5,3,TRUE)), IF(AND(B4="G1",M4="DG"),IF(R4="20'", VLOOKUP(Z4,Charge!$R$2:$T$5,2,TRUE)+(Z4-VLOOKUP(Z4,Charge!$R$2:$T$5,1,TRUE))*VLOOKUP(Z4,Charge!$R$2:$T$5,3,TRUE), VLOOKUP(Z4,Charge!$U$2:$W$5,2,TRUE)+(Z4-VLOOKUP(Z4,Charge!$U$2:$W$5,1,TRUE))*VLOOKUP(Z4,Charge!$U$2:$W$5,3,TRUE)), IF(AND(B4="G3",M4=""),IF(R4="20'", VLOOKUP(Z4,Charge!$K$18:$M$21,2,TRUE)+(Z4-VLOOKUP(Z4,Charge!$K$18:$M$21,1,TRUE))*VLOOKUP(Z4,Charge!$K$18:$M$21,3,TRUE), VLOOKUP(Z4,Charge!$N$18:$P$21,2,TRUE)+(Z4-VLOOKUP(Z4,Charge!$N$18:$P$21,1,TRUE))*VLOOKUP(Z4,Charge!$N$18:$P$21,3,TRUE)), IF(AND(B4="G3",M4="DG"),IF(R4="20'", VLOOKUP(Z4,Charge!$R$18:$T$21,2,TRUE)+(Z4-VLOOKUP(Z4,Charge!$R$18:$T$21,1,TRUE))*VLOOKUP(Z4,Charge!$R$18:$T$21,3,TRUE), VLOOKUP(Z4,Charge!$U$18:$W$21,2,TRUE)+(Z4-VLOOKUP(Z4,Charge!$U$18:$W$21,1,TRUE))*VLOOKUP(Z4,Charge!$U$18:$W$21,3,TRUE)), IF(AND(B4="G2",M4=""),IF(R4="20'", VLOOKUP(Z4,Charge!$K$9:$M$12,2,TRUE)+(Z4-VLOOKUP(Z4,Charge!$K$9:$M$12,1,TRUE))*VLOOKUP(Z4,Charge!$K$9:$M$12,3,TRUE), VLOOKUP(Z4,Charge!$N$9:$P$12,2,TRUE)+(Z4-VLOOKUP(Z4,Charge!$N$9:$P$12,1,TRUE))*VLOOKUP(Z4,Charge!$N$9:$P$12,3,TRUE)), IF(AND(B4="G2",M4="DG"),IF(R4="20'", VLOOKUP(Z4,Charge!$R$9:$T$12,2,TRUE)+(Z4-VLOOKUP(Z4,Charge!$R$9:$T$12,1,TRUE))*VLOOKUP(Z4,Charge!$R$9:$T$12,3,TRUE), VLOOKUP(Z4,Charge!$U$9:$W$12,2,TRUE)+(Z4-VLOOKUP(Z4,Charge!$U$9:$W$12,1,TRUE))*VLOOKUP(Z4,Charge!$U$9:$W$12,3,TRUE)),IF(AND(B4="G4",M4=""),IF(R4="20'",Z4*Charge!$M$25,Z4*Charge!$P$25),IF(AND(B4="G4",M4="DG"),IF(R4="20'",Z4*Charge!$T$25,Z4*Charge!$W$25),0)))))))) -> 0 | AD4: =IF(M4="DG",3,IF(N4="RF",3,5))+IF(AND(LEFT(C4,3)="BKK",N4="RF",Q4="KTS"),1,0)+IF(Q4="KHS",1,0) -> 5 | AE4: =(T4-V4)+1 -> 46304 | AF4: =IF(AB4>IF((V4-W4)>0,V4-W4,0),0,IF(AB4<IF((V4-W4)>0,V4-W4,0),IF((V4-W4)>0,V4-W4,0)-AB4,IF((V4-W4)>0,V4-W4,0))) -> 0 | AG4: =IF(AND(M4=""),IF(R4="20'", VLOOKUP(AF4,Charge!$K$31:$M$34,2,TRUE)+(AF4-VLOOKUP(AF4,Charge!$K$31:$M$34,1,TRUE))*VLOOKUP(AF4,Charge!$K$31:$M$34,3,TRUE), VLOOKUP(AF4,Charge!$N$31:$P$34,2,TRUE)+(AF4-VLOOKUP(AF4,Charge!$N$31:$P$34,1,TRUE))*VLOOKUP(AF4,Charge!$N$31:$P$34,3,TRUE)), IF(AND(M4="DG"),IF(R4="20'", VLOOKUP(AF4,Charge!$R$31:$T$34,2,TRUE)+(AF4-VLOOKUP(AF4,Charge!$R$31:$T$34,1,TRUE))*VLOOKUP(AF4,Charge!$R$31:$T$34,3,TRUE), VLOOKUP(AF4,Charge!$U$31:$W$34,2,TRUE)+(AF4-VLOOKUP(AF4,Charge!$U$31:$W$34,1,TRUE))*VLOOKUP(AF4,Charge!$U$31:$W$34,3,TRUE)),0)) -> 0 | AI4: =AA4-AH4 -> 0 | AK4: =VLOOKUP(D4,'2.Bookinglist'!A:CT,40,FALSE) -> Vilaiporn | AL4: =VLOOKUP(D4,'2.Bookinglist'!A:CW,101,FALSE) -> 2026-09-30 | AM4: =VLOOKUP(D4,'2.Bookinglist'!A:BK,63,FALSE) -> LCH27 | AN4: =VLOOKUP(D4,'2.Bookinglist'!A:AZ,52,FALSE) -> Pickup : 2026-09-23, Return : 2026-09-25 [1ST RTN 26/09/2026 W/O RENT] ** PLEASE CHECK OPEN GATE BEFORE RETURN CONTAINER ** | AO4: =VLOOKUP(D4,'2.Bookinglist'!A:CY,103,FALSE) -> 0
